Workbook

Sheet Instruction
B1: All in KB | D1: Tapis | E1: Dulang | F1: Jitang | G1: Sepat | H1: KIMC | I1: Kimanis | J1: Bintulu
A2: Day | B2: Ullage | C2: Processing Inventory | D2: Inventory_Base | E2: Inventory_A | F2: Inventory_B | G2: Inventory_C | H2: Inventory_D | I2: Inventory_E | J2: Inventory_F | K2: Rate_Base | L2: Rate_A | M2: Rate_B | N2: Rate_C | O2: Rate_D | P2: Rate_E | Q2: Rate_F | R2: primary_grade | S2: secondary_grade | T2: primary_rate | U2: secondary_rate | V2: total_rate | W2: ratio | X2: capacity_used | Y2: capacity_limit | Z2: Tank 1 | AA2: Tank 2 | AB2: Tank 3 | AC2: Tank 4 | AD2: Tank 5 | AE2: Delivery 1 | AF2: Delivery 2 | AG2: Delivery 3 | AH2: Delivery 4 | AI2: Delivery 5 | AJ2: Delivery 6 | AK2: Comment
A3: 0 | B3: =1180-C3 -> 1180 | C3: =SUM(D3:J3) -> 0 | AL3: Assumptions used:
A4: 1 | B4: =1180-C4 -> 1180 | C4: =SUM(D4:J4) -> 0 | D4: =D3-K4 -> 0 | E4: =E3-L4 -> 0 | F4: =F3-M4 -> 0 | G4: =G3-N4 -> 0 | H4: =H3-O4 -> 0 | I4: =I3-P4 -> 0 | J4: =J3-Q4 -> 0 | V4: =SUM(K4:Q4) -> 0 | W4: 0.60:0.40 | X4: 96 | Y4: 96 | AE4: Load Base (1-3) | AL4: 1. Assume 1 day loading, regardless of parcel size
A5: 2 | B5: =1180-C5 -> 1180 | C5: =SUM(D5:J5) -> 0 | D5: =D4-K5 -> 0 | E5: =E4-L5 -> 0 | F5: =F4-M5 -> 0 | G5: =G4-N5 -> 0 | H5: =H4-O5 -> 0 | I5: =I4-P5 -> 0 | J5: =J4-Q5 -> 0 | V5: =SUM(K5:Q5) -> 0 | W5: 0.60:0.40 | X5: 96 | Y5: 96 | AE5: Load A (1-3) | AL5: 2. Assume all spot vessel - no requirement to use the same vessel for subsequent voyage / consider sailing time from MRC to next loadport
A6: 3 | B6: =1180-C6 -> 1180 | C6: =SUM(D6:J6) -> 0 | D6: =D5-K6 -> 0 | E6: =E5-L6 -> 0 | F6: =F5-M6 -> 0 | G6: =G5-N6 -> 0 | H6: =H5-O6 -> 0 | I6: =I5-P6 -> 0 | J6: =J5-Q6 -> 0 | V6: =SUM(K6:Q6) -> 0 | W6: 0.60:0.40 | X6: 58 | Y6: 96 | AE6: Sail
A7: 4 | B7: =1180-C7 -> 1180 | C7: =SUM(D7:J7) -> 0 | D7: =D6-K7 -> 0 | E7: =E6-L7 -> 0 | F7: =F6-M7 -> 0 | G7: =G6-N7 -> 0 | H7: =H6-O7 -> 0 | I7: =I6-P7 -> 0 | J7: =J6-Q7 -> 0 | V7: =SUM(K7:Q7) -> 0 | W7: 0.27:0.73 | X7: 95 | Y7: 95 | AE7: Sail | AL7: 3. Max parcel for co-loading 2 grades: 700KB, 3 grades: 650KB
A8: 5 | B8: =1180-C8 -> 1180 | C8: =SUM(D8:J8) -> 0 | D8: =D7-K8 -> 0 | E8: =E7-L8 -> 0 | F8: =F7-M8 -> 0 | G8: =G7-N8 -> 0 | H8: =H7-O8 -> 0 | I8: =I7-P8 -> 0 | J8: =J7-Q8 -> 0 | V8: =SUM(K8:Q8) -> 0 | W8: 0.27:0.73 | X8: 96 | Y8: 96 | AE8: Discharge | AF8: Load E (5-7) | AL8: 4. Sailing time assumption - refer to table
A9: 6 | B9: =1180-C9 -> 1180 | C9: =SUM(D9:J9) -> 0 | D9: =D8-K9 -> 0 | E9: =E8-L9 -> 0 | F9: =F8-M9 -> 0 | G9: =G8-N9 -> 0 | H9: =H8-O9 -> 0 | I9: =I8-P9 -> 0 | J9: =J8-Q9 -> 0 | V9: =SUM(K9:Q9) -> 0 | W9: 0.27:0.73 | X9: 96 | Y9: 96 | AE9: Discharge | AF9: Sail to Sarawak | AL9: 5. Do not assume ROB
A10: 7 | B10: =1180-C10 -> 1180 | C10: =SUM(D10:J10) -> 0 | D10: =D9-K10 -> 0 | E10: =E9-L10 -> 0 | F10: =F9-M10 -> 0 | G10: =G9-N10 -> 0 | H10: =H9-O10 -> 0 | I10: =I9-P10 -> 0 | J10: =J9-Q10 -> 0 | V10: =SUM(K10:Q10) -> 0 | W10: 0.27:0.73 | X10: 96 | Y10: 96 | AE10: Tk prep | AF10: Load F (5-7)
A11: 8 | B11: =1180-C11 -> 1180 | C11: =SUM(D11:J11) -> 0 | D11: =D10-K11 -> 0 | E11: =E10-L11 -> 0 | F11: =F10-M11 -> 0 | G11: =G10-N11 -> 0 | H11: =H10-O11 -> 0 | I11: =I10-P11 -> 0 | J11: =J10-Q11 -> 0 | V11: =SUM(K11:Q11) -> 0 | W11: 0.27:0.73 | X11: 96 | Y11: 96 | AE11: Tk prep | AF11: Sail
A12: 9 | B12: =1180-C12 -> 1180 | C12: =SUM(D12:J12) -> 0 | D12: =D11-K12 -> 0 | E12: =E11-L12 -> 0 | F12: =F11-M12 -> 0 | G12: =G11-N12 -> 0 | H12: =H11-O12 -> 0 | I12: =I11-P12 -> 0 | J12: =J11-Q12 -> 0 | V12: =SUM(K12:Q12) -> 0 | W12: 0.27:0.73 | X12: 96 | Y12: 96 | AE12: Tk prep | AF12: Sail
A13: 10 | B13: =1180-C13 -> 1180 | C13: =SUM(D13:J13) -> 0 | D13: =D12-K13 -> 0 | E13: =E12-L13 -> 0 | F13: =F12-M13 -> 0 | G13: =G12-N13 -> 0 | H13: =H12-O13 -> 0 | I13: =I12-P13 -> 0 | J13: =J12-Q13 -> 0 | V13: =SUM(K13:Q13) -> 0 | W13: 0.27:0.73 | X13: 75.555556 | Y13: 96 | AE13: Base: 400, A :150 | AF13: Sail | AG13: Load B (8-10)
A14: 11 | B14: =1180-C14 -> 1180 | C14: =SUM(D14:J14) -> 0 | D14: =D13-K14 -> 0 | E14: =E13-L14 -> 0 | F14: =F13-M14 -> 0 | G14: =G13-N14 -> 0 | H14: =H13-O14 -> 0 | I14: =I13-P14 -> 0 | J14: =J13-Q14 -> 0 | V14: =SUM(K14:Q14) -> 0 | W14: 0.27:0.73 | X14: 95 | Y14: 95 | AF14: Discharge | AG14: Sail | AH14: Load E (10-11)
A15: 12 | B15: =1180-C15 -> 1180 | C15: =SUM(D15:J15) -> 0 | D15: =D14-K15 -> 0 | E15: =E14-L15 -> 0 | F15: =F14-M15 -> 0 | G15: =G14-N15 -> 0 | H15: =H14-O15 -> 0 | I15: =I14-P15 -> 0 | J15: =J14-Q15 -> 0 | V15: =SUM(K15:Q15) -> 0 | W15: 0.27:0.73 | X15: 95 | Y15: 95 | AF15: Discharge | AG15: Sail | AH15: Sail
A16: 13 | B16: =1180-C16 -> 1180 | C16: =SUM(D16:J16) -> 0 | D16: =D15-K16 -> 0 | E16: =E15-L16 -> 0 | F16: =F15-M16 -> 0 | G16: =G15-N16 -> 0 | H16: =H15-O16 -> 0 | I16: =I15-P16 -> 0 | J16: =J15-Q16 -> 0 | V16: =SUM(K16:Q16) -> 0 | W16: 0.27:0.73 | X16: 95 | Y16: 95 | AF16: Tank Prep | AG16: Discharge | AH16: Sail
A17: 14 | B17: =1180-C17 -> 1180 | C17: =SUM(D17:J17) -> 0 | D17: =D16-K17 -> 0 | E17: =E16-L17 -> 0 | F17: =F16-M17 -> 0 | G17: =G16-N17 -> 0 | H17: =H16-O17 -> 0 | I17: =I16-P17 -> 0 | J17: =J16-Q17 -> 0 | V17: =SUM(K17:Q17) -> 0 | W17: 0.27:0.73 | X17: 91.841705 | Y17: 95 | AF17: Tank Prep | AG17: Discharge | AH17: Sail
A18: 15 | B18: =1180-C18 -> 1180 | C18: =SUM(D18:J18) -> 0 | D18: =D17-K18 -> 0 | E18: =E17-L18 -> 0 | F18: =F17-M18 -> 0 | G18: =G17-N18 -> 0 | H18: =H17-O18 -> 0 | I18: =I17-P18 -> 0 | J18: =J17-Q18 -> 0 | V18: =SUM(K18:Q18) -> 0 | W18: 1.00:0.00 | X18: 7.1054274e-15 | Y18: 96 | AF18: Tank Prep | AG18: Tank Prep | AH18: Demurrage
A19: 16 | B19: =1180-C19 -> 1180 | C19: =SUM(D19:J19) -> 0 | D19: =D18-K19 -> 0 | E19: =E18-L19 -> 0 | F19: =F18-M19 -> 0 | G19: =G18-N19 -> 0 | H19: =H18-O19 -> 0 | I19: =I18-P19 -> 0 | J19: =J18-Q19 -> 0 | V19: =SUM(K19:Q19) -> 0 | W19: 1.00:0.00 | X19: 95 | Y19: 95 | AF19: E: 250, F: 320 | AG19: Tank Prep | AH19: Demurrage
A20: 17 | B20: =1180-C20 -> 1180 | C20: =SUM(D20:J20) -> 0 | D20: =D19-K20 -> 0 | E20: =E19-L20 -> 0 | F20: =F19-M20 -> 0 | G20: =G19-N20 -> 0 | H20: =H19-O20 -> 0 | I20: =I19-P20 -> 0 | J20: =J19-Q20 -> 0 | V20: =SUM(K20:Q20) -> 0 | W20: 1.00:0.00 | X20: 77.60274 | Y20: 95 | AG20: Tank Prep | AH20: Discharge
A21: 18 | B21: =1180-C21 -> 1180 | C21: =SUM(D21:J21) -> 0 | D21: =D20-K21 -> 0 | E21: =E20-L21 -> 0 | F21: =F20-M21 -> 0 | G21: =G20-N21 -> 0 | H21: =H20-O21 -> 0 | I21: =I20-P21 -> 0 | J21: =J20-Q21 -> 0 | V21: =SUM(K21:Q21) -> 0 | W21: 1.00:0.00 | X21: 95 | Y21: 95 | AG21: B: 150 | AH21: Discharge | AI21: Load Base (17-19)
A22: 19 | B22: =1180-C22 -> 1180 | C22: =SUM(D22:J22) -> 0 | D22: =D21-K22 -> 0 | E22: =E21-L22 -> 0 | F22: =F21-M22 -> 0 | G22: =G21-N22 -> 0 | H22: =H21-O22 -> 0 | I22: =I21-P22 -> 0 | J22: =J21-Q22 -> 0 | V22: =SUM(K22:Q22) -> 0 | W22: 1.00:0.00 | X22: 96 | Y22: 96 | AH22: Tank Prep | AI22: Load C (17-19)
A23: 20 | B23: =1180-C23 -> 1180 | C23: =SUM(D23:J23) -> 0 | D23: =D22-K23 -> 0 | E23: =E22-L23 -> 0 | F23: =F22-M23 -> 0 | G23: =G22-N23 -> 0 | H23: =H22-O23 -> 0 | I23: =I22-P23 -> 0 | J23: =J22-Q23 -> 0 | V23: =SUM(K23:Q23) -> 0 | W23: 1.00:0.00 | X23: 96 | Y23: 96 | AH23: Tank Prep | AI23: Sail
A24: 21 | B24: =1180-C24 -> 1180 | C24: =SUM(D24:J24) -> 0 | D24: =D23-K24 -> 0 | E24: =E23-L24 -> 0 | F24: =F23-M24 -> 0 | G24: =G23-N24 -> 0 | H24: =H23-O24 -> 0 | I24: =I23-P24 -> 0 | J24: =J23-Q24 -> 0 | V24: =SUM(K24:Q24) -> 0 | W24: 1.00:0.00 | X24: 8 | Y24: 96 | AH24: Tank Prep | AI24: Sail | AJ24: Load F (19-22)
A25: 22 | B25: =1180-C25 -> 1180 | C25: =SUM(D25:J25) -> 0 | D25: =D24-K25 -> 0 | E25: =E24-L25 -> 0 | F25: =F24-M25 -> 0 | G25: =G24-N25 -> 0 | H25: =H24-O25 -> 0 | I25: =I24-P25 -> 0 | J25: =J24-Q25 -> 0 | V25: =SUM(K25:Q25) -> 0 | W25: 1.00:0.00 | X25: 87 | Y25: 87 | AH25: E: 550 | AI25: Demurrage | AJ25: Sail to Sabah
A26: 23 | B26: =1180-C26 -> 1180 | C26: =SUM(D26:J26) -> 0 | D26: =D25-K26 -> 0 | E26: =E25-L26 -> 0 | F26: =F25-M26 -> 0 | G26: =G25-N26 -> 0 | H26: =H25-O26 -> 0 | I26: =I25-P26 -> 0 | J26: =J25-Q26 -> 0 | V26: =SUM(K26:Q26) -> 0 | W26: 1.00:0.00 | X26: 87 | Y26: 87 | AI26: Discharge | AJ26: Load E (23-24)
A27: 24 | B27: =1180-C27 -> 1180 | C27: =SUM(D27:J27) -> 0 | D27: =D26-K27 -> 0 | E27: =E26-L27 -> 0 | F27: =F26-M27 -> 0 | G27: =G26-N27 -> 0 | H27: =H26-O27 -> 0 | I27: =I26-P27 -> 0 | J27: =J26-Q27 -> 0 | V27: =SUM(K27:Q27) -> 0 | W27: 1.00:0.00 | X27: 87 | Y27: 87 | AI27: Discharge | AJ27: Load D (23-24)
A28: 25 | B28: =1180-C28 -> 1180 | C28: =SUM(D28:J28) -> 0 | D28: =D27-K28 -> 0 | E28: =E27-L28 -> 0 | F28: =F27-M28 -> 0 | G28: =G27-N28 -> 0 | H28: =H27-O28 -> 0 | I28: =I27-P28 -> 0 | J28: =J27-Q28 -> 0 | V28: =SUM(K28:Q28) -> 0 | W28: 1.00:0.00 | X28: 87 | Y28: 87 | AI28: Tank Prep | AJ28: Sail
A29: 26 | B29: =1180-C29 -> 1180 | C29: =SUM(D29:J29) -> 0 | D29: =D28-K29 -> 0 | E29: =E28-L29 -> 0 | F29: =F28-M29 -> 0 | G29: =G28-N29 -> 0 | H29: =H28-O29 -> 0 | I29: =I28-P29 -> 0 | J29: =J28-Q29 -> 0 | V29: =SUM(K29:Q29) -> 0 | W29: 1.00:0.00 | X29: 12 | Y29: 87 | AI29: Tank Prep | AJ29: Sail
A30: 27 | B30: =1180-C30 -> 1180 | C30: =SUM(D30:J30) -> 0 | D30: =D29-K30 -> 0 | E30: =E29-L30 -> 0 | F30: =F29-M30 -> 0 | G30: =G29-N30 -> 0 | H30: =H29-O30 -> 0 | I30: =I29-P30 -> 0 | J30: =J29-Q30 -> 0 | V30: =SUM(K30:Q30) -> 0 | W30: 1.00:0.00 | X30: 95 | Y30: 95 | AI30: Tank Prep | AJ30: Sail
A31: 28 | B31: =1180-C31 -> 1180 | C31: =SUM(D31:J31) -> 0 | D31: =D30-K31 -> 0 | E31: =E30-L31 -> 0 | F31: =F30-M31 -> 0 | G31: =G30-N31 -> 0 | H31: =H30-O31 -> 0 | I31: =I30-P31 -> 0 | J31: =J30-Q31 -> 0 | V31: =SUM(K31:Q31) -> 0 | W31: 1.00:0.00 | X31: 55 | Y31: 95 | AI31: Base: 360, C: 200 | AJ31: Discharge
A32: 29 | B32: =1180-C32 -> 1180 | C32: =SUM(D32:J32) -> 0 | D32: =D31-K32 -> 0 | E32: =E31-L32 -> 0 | F32: =F31-M32 -> 0 | G32: =G31-N32 -> 0 | H32: =H31-O32 -> 0 | I32: =I31-P32 -> 0 | J32: =J31-Q32 -> 0 | V32: =SUM(K32:Q32) -> 0 | W32: 1.00:0.00 | X32: 95 | Y32: 95 | AJ32: Discharge
A33: 30 | B33: =1180-C33 -> 1180 | C33: =SUM(D33:J33) -> 0 | D33: =D32-K33 -> 0 | E33: =E32-L33 -> 0 | F33: =F32-M33 -> 0 | G33: =G32-N33 -> 0 | H33: =H32-O33 -> 0 | I33: =I32-P33 -> 0 | J33: =J32-Q33 -> 0 | V33: =SUM(K33:Q33) -> 0 | W33: 1.00:0.00 | X33: 95 | Y33: 95 | AJ33: Tank Prep
A34: 31 | B34: =1180-C34 -> 1180 | C34: =SUM(D34:J34) -> 0 | D34: =D33-K34 -> 0 | E34: =E33-L34 -> 0 | F34: =F33-M34 -> 0 | G34: =G33-N34 -> 0 | H34: =H33-O34 -> 0 | I34: =I33-P34 -> 0 | J34: =J33-Q34 -> 0 | V34: =SUM(K34:Q34) -> 0 | AJ34: Tank Prep
A35: 32 | B35: =1180-C35 -> 1180 | C35: =SUM(D35:J35) -> 0 | D35: =D34-K35 -> 0 | E35: =E34-L35 -> 0 | F35: =F34-M35 -> 0 | G35: =G34-N35 -> 0 | H35: =H34-O35 -> 0 | I35: =I34-P35 -> 0 | J35: =J34-Q35 -> 0 | V35: =SUM(K35:Q35) -> 0 | AJ35: Tank Prep
A36: 33 | B36: =1180-C36 -> 1180 | C36: =SUM(D36:J36) -> 0 | D36: =D35-K36 -> 0 | E36: =E35-L36 -> 0 | F36: =F35-M36 -> 0 | G36: =G35-N36 -> 0 | H36: =H35-O36 -> 0 | I36: =I35-P36 -> 0 | J36: =J35-Q36 -> 0 | V36: =SUM(K36:Q36) -> 0 | AJ36: F: 280, E: 100, D: 150
A37: 34 | B37: =1180-C37 -> 1180 | C37: =SUM(D37:J37) -> 0 | D37: =D36-K37 -> 0 | E37: =E36-L37 -> 0 | F37: =F36-M37 -> 0 | G37: =G36-N37 -> 0 | H37: =H36-O37 -> 0 | I37: =I36-P37 -> 0 | J37: =J36-Q37 -> 0 | V37: =SUM(K37:Q37) -> 0
A38: 35 | B38: =1180-C38 -> 1180 | C38: =SUM(D38:J38) -> 0 | D38: =D37-K38 -> 0 | E38: =E37-L38 -> 0 | F38: =F37-M38 -> 0 | G38: =G37-N38 -> 0 | H38: =H37-O38 -> 0 | I38: =I37-P38 -> 0 | J38: =J37-Q38 -> 0 | V38: =SUM(K38:Q38) -> 0
A39: 36 | B39: =1180-C39 -> 1180 | C39: =SUM(D39:J39) -> 0 | D39: =D38-K39 -> 0 | E39: =E38-L39 -> 0 | F39: =F38-M39 -> 0 | G39: =G38-N39 -> 0 | H39: =H38-O39 -> 0 | I39: =I38-P39 -> 0 | J39: =J38-Q39 -> 0 | V39: =SUM(K39:Q39) -> 0
A40: 37 | B40: =1180-C40 -> 1180 | C40: =SUM(D40:J40) -> 0 | D40: =D39-K40 -> 0 | E40: =E39-L40 -> 0 | F40: =F39-M40 -> 0 | G40: =G39-N40 -> 0 | H40: =H39-O40 -> 0 | I40: =I39-P40 -> 0 | J40: =J39-Q40 -> 0 | V40: =SUM(K40:Q40) -> 0
...

Sheet Summary
C1: Summary for 40 days
A2: Scenario | B2: CDU-1 Rate 30 days | C2: CDU-1 Rate 40 days | D2: No. of Cargo Delivery | E2: Additional Freight Cost* | F2: Demurrage days | G2: Demurrage Cost** | H2: Total Crude Margin | I2: Net Profit Margin
B3: (kbd) | C3: (kbd) | D3: # | E3: (USD k) | F3: (day) | G3: (USD k) | H3: (USD k)
A4: Template | B4: =Template!V47 -> 0 | C4: =Template!V48 -> 0 | E4: =IF(D4>5,(D4-5)*600,0) -> 0 | F4: =Template!V55 -> 0 | G4: =F4*40 -> 0 | H4: =Template!W45 -> 0 | I4: =H4-E4-G4 -> 0 | J4: For M-2, Oct 2025
A5: Base case | B5: ='Base Case (Working)'!V47 -> 93.866667 | C5: ='Base Case (Working)'!V48 -> 92.875 | D5: 6 | E5: =IF(D5>5,(D5-5)*600,0) -> 600 | F5: ='Base Case (Working)'!V55 -> 3 | G5: =F5*40 -> 120 | H5: ='Base Case (Working)'!W45 -> 48296.19 | I5: =H5-E5-G5 -> 47576.19 | J5: PoC OASIS
A6: Scenario 2 | B6: ='Scenario 2'!V45 -> 94.229383 | C6: ='Scenario 2'!V46 -> 94.406234 | D6: 6 | E6: =IF(D6>5,(D6-5)*600,0) -> 600 | F6: ='Scenario 2'!V53 -> 1 | G6: =F6*40 -> 40 | H6: ='Scenario 2'!W44 -> 48301.771 | I6: =H6-E6-G6 -> 47661.771
A7: Scenario 3 | B7: ='Scenario 3'!X45 -> 93.310731 | C7: ='Scenario 3'!X46 -> 89.46 | D7: 6 | E7: =IF(D7>5,(D7-5)*600,0) -> 600 | F7: ='Scenario 3'!X53 -> 10 | G7: =F7*40 -> 400 | H7: ='Scenario 3'!Y44 -> 31138.906 | I7: =H7-E7-G7 -> 30138.906
A8: Scenario 4 | B8: ='Scenario 4'!V45 -> 90.233356 | C8: ='Scenario 4'!V46 -> 91.600017 | D8: 6 | E8: =IF(D8>5,(D8-5)*600,0) -> 600 | F8: ='Scenario 4'!V54 -> 3 | G8: =F8*40 -> 120 | H8: ='Scenario 4'!W44 -> 48187.418 | I8: =H8-E8-G8 -> 47467.418
A9: Sencario 5a | B9: ='Scenario 5a'!V45 -> 85.759932 | C9: ='Scenario 5a'!V46 -> 88.077825 | D9: 6 | E9: =IF(D9>5,(D9-5)*600,0) -> 600 | F9: ='Scenario 5a'!V54 -> 10 | G9: =F9*40 -> 400 | H9: ='Scenario 5a'!W44 -> 46835.401 | I9: =H9-E9-G9 -> 45835.401
A10: Sencario 5b | B10: ='Scenario 5b'!V45 -> 88.371994 | C10: ='Scenario 5b'!V46 -> 90.058408 | D10: 6 | E10: =IF(D10>5,(D10-5)*600,0) -> 600 | F10: ='Scenario 5b'!V54 -> 12 | G10: =F10*40 -> 480 | H10: ='Scenario 5b'!W44 -> 48171.737 | I10: =H10-E10-G10 -> 47091.737
A11: Sencario 5c | B11: ='Scenario 5c'!V45 -> 95.233356 | C11: ='Scenario 5c'!V46 -> 95.225017 | D11: 6 | E11: =IF(D11>5,(D11-5)*600,0) -> 600 | F11: ='Scenario 5c'!V54 -> 9 | G11: =F11*40 -> 360 | H11: ='Scenario 5c'!W44 -> 50107.549 | I11: =H11-E11-G11 -> 49147.549
A15: Reference:
B16: = Auto-calculate formula
B17: = User input
B18: Margin (USD/bbl)
B19: Crude Grade | C19: Oct
A20: Tapis | B20: Base | C20: 15.85
A21: Dulang | B21: A | C21: 18.47
A22: Jitang | B22: B | C22: 15.71
A23: Sepat | B23: C | C23: 19.24
A24: KimC (condy) | B24: D | C24: 11.19
A25: Kimanis (crude) | B25: E | C25: 9.98
A26: Bintulu | B26: F | C26: 9.97
A27: Cendor | B27: G
A28: Kidurong | B28: H
A30: *no additional freight cost up to 5 delivery per month. Freight cost: USD 600k/ delivery if more than 5 cargo delivery)
A31: **Demurrage cost : | B31: USD 40k/ day

Sheet Template
B1: All in KB | D1: Tapis | E1: Dulang | F1: Jitang | G1: Sepat | H1: KIMC | I1: Kimanis | J1: Bintulu
A2: Day | B2: Ullage | C2: Processing Inventory | D2: Inventory_Base | E2: Inventory_A | F2: Inventory_B | G2: Inventory_C | H2: Inventory_D | I2: Inventory_E | J2: Inventory_F | K2: Rate_Base | L2: Rate_A | M2: Rate_B | N2: Rate_C | O2: Rate_D | P2: Rate_E | Q2: Rate_F | R2: primary_grade | S2: secondary_grade | T2: primary_rate | U2: secondary_rate | V2: total_rate | W2: Crude Margin (USD k) | X2: ratio | Y2: capacity_used | Z2: capacity_limit | AA2: Tank 1 | AB2: Tank 2 | AC2: Tank 3 | AD2: Tank 4 | AE2: Tank 5 | AF2: Delivery 1 | AG2: Delivery 2 | AH2: Delivery 3 | AI2: Delivery 4 | AJ2: Delivery 5 | AK2: Delivery 6 | AL2: Comment
A3: 0 | B3: =1180-C3 -> 130 | C3: =SUM(D3:J3) -> 1050 | D3: 350 | E3: 0 | F3: 150 | G3: 150 | H3: 100 | I3: 0 | J3: 300 | K3: 0 | L3: 0 | M3: 0 | N3: 0 | O3: 0 | P3: 0 | Q3: 0 | V3: 0
A4: 1 | B4: =1180-C4 -> 130 | C4: =SUM(D4:J4) -> 1050 | D4: =D3-K4 -> 350 | E4: =E3-L4 -> 0 | F4: =F3-M4 -> 150 | G4: =G3-N4 -> 150 | H4: =H3-O4 -> 100 | I4: =I3-P4 -> 0 | J4: =J3-Q4 -> 300 | R4: C | S4: D | T4: 57.6 | U4: 38.4 | V4: =SUM(K4:Q4) -> 0 | W4: =Summary!$C$20*K4+Summary!$C$21*L4+Summary!$C$22*M4+Summary!$C$23*N4+Summary!$C$24*O4+Summary!$C$25*P4+Summary!$C$26*Q4 -> 0 | X4: 0.60:0.40 | Y4: 96 | Z4: 96
A5: 2 | B5: =1180-C5 -> 130 | C5: =SUM(D5:J5) -> 1050 | D5: =D4-K5 -> 350 | E5: =E4-L5 -> 0 | F5: =F4-M5 -> 150 | G5: =G4-N5 -> 150 | H5: =H4-O5 -> 100 | I5: =I4-P5 -> 0 | J5: =J4-Q5 -> 300 | R5: C | S5: D | T5: 57.6 | U5: 38.4 | V5: =SUM(K5:Q5) -> 0 | W5: =Summary!$C$20*K5+Summary!$C$21*L5+Summary!$C$22*M5+Summary!$C$23*N5+Summary!$C$24*O5+Summary!$C$25*P5+Summary!$C$26*Q5 -> 0 | X5: 0.60:0.40 | Y5: 96 | Z5: 96
A6: 3 | B6: =1180-C6 -> 130 | C6: =SUM(D6:J6) -> 1050 | D6: =D5-K6 -> 350 | E6: =E5-L6 -> 0 | F6: =F5-M6 -> 150 | G6: =G5-N6 -> 150 | H6: =H5-O6 -> 100 | I6: =I5-P6 -> 0 | J6: =J5-Q6 -> 300 | R6: C | S6: D | T6: 34.8 | U6: 23.2 | V6: =SUM(K6:Q6) -> 0 | W6: =Summary!$C$20*K6+Summary!$C$21*L6+Summary!$C$22*M6+Summary!$C$23*N6+Summary!$C$24*O6+Summary!$C$25*P6+Summary!$C$26*Q6 -> 0 | X6: 0.60:0.40 | Y6: 58 | Z6: 96
A7: 4 | B7: =1180-C7 -> 130 | C7: =SUM(D7:J7) -> 1050 | D7: =D6-K7 -> 350 | E7: =E6-L7 -> 0 | F7: =F6-M7 -> 150 | G7: =G6-N7 -> 150 | H7: =H6-O7 -> 100 | I7: =I6-P7 -> 0 | J7: =J6-Q7 -> 300 | R7: B | S7: Base | T7: 25.65 | U7: 69.35 | V7: =SUM(K7:Q7) -> 0 | W7: =Summary!$C$20*K7+Summary!$C$21*L7+Summary!$C$22*M7+Summary!$C$23*N7+Summary!$C$24*O7+Summary!$C$25*P7+Summary!$C$26*Q7 -> 0 | X7: 0.27:0.73 | Y7: 95 | Z7: 95
A8: 5 | B8: =1180-C8 -> 130 | C8: =SUM(D8:J8) -> 1050 | D8: =D7-K8 -> 350 | E8: =E7-L8 -> 0 | F8: =F7-M8 -> 150 | G8: =G7-N8 -> 150 | H8: =H7-O8 -> 100 | I8: =I7-P8 -> 0 | J8: =J7-Q8 -> 300 | R8: A | S8: Base | T8: 25.92 | U8: 70.08 | V8: =SUM(K8:Q8) -> 0 | W8: =Summary!$C$20*K8+Summary!$C$21*L8+Summary!$C$22*M8+Summary!$C$23*N8+Summary!$C$24*O8+Summary!$C$25*P8+Summary!$C$26*Q8 -> 0 | X8: 0.27:0.73 | Y8: 96 | Z8: 96
A9: 6 | B9: =1180-C9 -> -420 | C9: =SUM(D9:J9) -> 1600 | D9: =D8-K9+400 -> 750 | E9: =E8-L9+150 -> 150 | F9: =F8-M9 -> 150 | G9: =G8-N9 -> 150 | H9: =H8-O9 -> 100 | I9: =I8-P9 -> 0 | J9: =J8-Q9 -> 300 | R9: A | S9: Base | T9: 25.92 | U9: 70.08 | V9: =SUM(K9:Q9) -> 0 | W9: =Summary!$C$20*K9+Summary!$C$21*L9+Summary!$C$22*M9+Summary!$C$23*N9+Summary!$C$24*O9+Summary!$C$25*P9+Summary!$C$26*Q9 -> 0 | X9: 0.27:0.73 | Y9: 96 | Z9: 96
A10: 7 | B10: =1180-C10 -> -420 | C10: =SUM(D10:J10) -> 1600 | D10: =D9-K10 -> 750 | E10: =E9-L10 -> 150 | F10: =F9-M10 -> 150 | G10: =G9-N10 -> 150 | H10: =H9-O10 -> 100 | I10: =I9-P10 -> 0 | J10: =J9-Q10 -> 300 | R10: A | S10: Base | T10: 25.92 | U10: 70.08 | V10: =SUM(K10:Q10) -> 0 | W10: =Summary!$C$20*K10+Summary!$C$21*L10+Summary!$C$22*M10+Summary!$C$23*N10+Summary!$C$24*O10+Summary!$C$25*P10+Summary!$C$26*Q10 -> 0 | X10: 0.27:0.73 | Y10: 96 | Z10: 96
A11: 8 | B11: =1180-C11 -> -420 | C11: =SUM(D11:J11) -> 1600 | D11: =D10-K11 -> 750 | E11: =E10-L11 -> 150 | F11: =F10-M11 -> 150 | G11: =G10-N11 -> 150 | H11: =H10-O11 -> 100 | I11: =I10-P11 -> 0 | J11: =J10-Q11 -> 300 | R11: A | S11: Base | T11: 25.92 | U11: 70.08 | V11: =SUM(K11:Q11) -> 0 | W11: =Summary!$C$20*K11+Summary!$C$21*L11+Summary!$C$22*M11+Summary!$C$23*N11+Summary!$C$24*O11+Summary!$C$25*P11+Summary!$C$26*Q11 -> 0 | X11: 0.27:0.73 | Y11: 96 | Z11: 96
A12: 9 | B12: =1180-C12 -> -420 | C12: =SUM(D12:J12) -> 1600 | D12: =D11-K12 -> 750 | E12: =E11-L12 -> 150 | F12: =F11-M12 -> 150 | G12: =G11-N12 -> 150 | H12: =H11-O12 -> 100 | I12: =I11-P12 -> 0 | J12: =J11-Q12 -> 300 | R12: A | S12: Base | T12: 25.92 | U12: 70.08 | V12: =SUM(K12:Q12) -> 0 | W12: =Summary!$C$20*K12+Summary!$C$21*L12+Summary!$C$22*M12+Summary!$C$23*N12+Summary!$C$24*O12+Summary!$C$25*P12+Summary!$C$26*Q12 -> 0 | X12: 0.27:0.73 | Y12: 96 | Z12: 96
A13: 10 | B13: =1180-C13 -> -420 | C13: =SUM(D13:J13) -> 1600 | D13: =D12-K13 -> 750 | E13: =E12-L13 -> 150 | F13: =F12-M13 -> 150 | G13: =G12-N13 -> 150 | H13: =H12-O13 -> 100 | I13: =I12-P13 -> 0 | J13: =J12-Q13 -> 300 | R13: A | S13: Base | T13: 20.4 | U13: 55.155556 | V13: =SUM(K13:Q13) -> 0 | W13: =Summary!$C$20*K13+Summary!$C$21*L13+Summary!$C$22*M13+Summary!$C$23*N13+Summary!$C$24*O13+Summary!$C$25*P13+Summary!$C$26*Q13 -> 0 | X13: 0.27:0.73 | Y13: 75.555556 | Z13: 96
A14: 11 | B14: =1180-C14 -> -420 | C14: =SUM(D14:J14) -> 1600 | D14: =D13-K14 -> 750 | E14: =E13-L14 -> 150 | F14: =F13-M14 -> 150 | G14: =G13-N14 -> 150 | H14: =H13-O14 -> 100 | I14: =I13-P14 -> 0 | J14: =J13-Q14 -> 300 | R14: B | S14: Base | T14: 25.65 | U14: 69.35 | V14: =SUM(K14:Q14) -> 0 | W14: =Summary!$C$20*K14+Summary!$C$21*L14+Summary!$C$22*M14+Summary!$C$23*N14+Summary!$C$24*O14+Summary!$C$25*P14+Summary!$C$26*Q14 -> 0 | X14: 0.27:0.73 | Y14: 95 | Z14: 95
A15: 12 | B15: =1180-C15 -> -990 | C15: =SUM(D15:J15) -> 2170 | D15: =D14-K15 -> 750 | E15: =E14-L15 -> 150 | F15: =F14-M15 -> 150 | G15: =G14-N15 -> 150 | H15: =H14-O15 -> 100 | I15: =I14-P15+250 -> 250 | J15: =J14-Q15+320 -> 620 | R15: B | S15: Base | T15: 25.65 | U15: 69.35 | V15: =SUM(K15:Q15) -> 0 | W15: =Summary!$C$20*K15+Summary!$C$21*L15+Summary!$C$22*M15+Summary!$C$23*N15+Summary!$C$24*O15+Summary!$C$25*P15+Summary!$C$26*Q15 -> 0 | X15: 0.27:0.73 | Y15: 95 | Z15: 95
A16: 13 | B16: =1180-C16 -> -990 | C16: =SUM(D16:J16) -> 2170 | D16: =D15-K16 -> 750 | E16: =E15-L16 -> 150 | F16: =F15-M16 -> 150 | G16: =G15-N16 -> 150 | H16: =H15-O16 -> 100 | I16: =I15-P16 -> 250 | J16: =J15-Q16 -> 620 | R16: B | S16: Base | T16: 25.65 | U16: 69.35 | V16: =SUM(K16:Q16) -> 0 | W16: =Summary!$C$20*K16+Summary!$C$21*L16+Summary!$C$22*M16+Summary!$C$23*N16+Summary!$C$24*O16+Summary!$C$25*P16+Summary!$C$26*Q16 -> 0 | X16: 0.27:0.73 | Y16: 95 | Z16: 95
A17: 14 | B17: =1180-C17 -> -1140 | C17: =SUM(D17:J17) -> 2320 | D17: =D16-K17 -> 750 | E17: =E16-L17 -> 150 | F17: =F16-M17 + 150 -> 300 | G17: =G16-N17 -> 150 | H17: =H16-O17 -> 100 | I17: =I16-P17 -> 250 | J17: =J16-Q17 -> 620 | R17: B | S17: Base | T17: 24.79726 | U17: 67.044444 | V17: =SUM(K17:Q17) -> 0 | W17: =Summary!$C$20*K17+Summary!$C$21*L17+Summary!$C$22*M17+Summary!$C$23*N17+Summary!$C$24*O17+Summary!$C$25*P17+Summary!$C$26*Q17 -> 0 | X17: 0.27:0.73 | Y17: 91.841705 | Z17: 95
A18: 15 | B18: =1180-C18 -> -1140 | C18: =SUM(D18:J18) -> 2320 | D18: =D17-K18 -> 750 | E18: =E17-L18 -> 150 | F18: =F17-M18 -> 300 | G18: =G17-N18 -> 150 | H18: =H17-O18 -> 100 | I18: =I17-P18 -> 250 | J18: =J17-Q18 -> 620 | R18: C | T18: 7.1054274e-15 | U18: 0 | V18: =SUM(K18:Q18) -> 0 | W18: =Summary!$C$20*K18+Summary!$C$21*L18+Summary!$C$22*M18+Summary!$C$23*N18+Summary!$C$24*O18+Summary!$C$25*P18+Summary!$C$26*Q18 -> 0 | X18: 1.00:0.00 | Y18: 7.1054274e-15 | Z18: 96
A19: 16 | B19: =1180-C19 -> -1140 | C19: =SUM(D19:J19) -> 2320 | D19: =D18-K19 -> 750 | E19: =E18-L19 -> 150 | F19: =F18-M19 -> 300 | G19: =G18-N19 -> 150 | H19: =H18-O19 -> 100 | I19: =I18-P19 -> 250 | J19: =J18-Q19 -> 620 | R19: B | T19: 95 | U19: 0 | V19: =SUM(K19:Q19) -> 0 | W19: =Summary!$C$20*K19+Summary!$C$21*L19+Summary!$C$22*M19+Summary!$C$23*N19+Summary!$C$24*O19+Summary!$C$25*P19+Summary!$C$26*Q19 -> 0 | X19: 1.00:0.00 | Y19: 95 | Z19: 95
A20: 17 | B20: =1180-C20 -> -1140 | C20: =SUM(D20:J20) -> 2320 | D20: =D19-K20 -> 750 | E20: =E19-L20 -> 150 | F20: =F19-M20 -> 300 | G20: =G19-N20 -> 150 | H20: =H19-O20 -> 100 | I20: =I19-P20 -> 250 | J20: =J19-Q20 -> 620 | R20: B | T20: 77.60274 | U20: 0 | V20: =SUM(K20:Q20) -> 0 | W20: =Summary!$C$20*K20+Summary!$C$21*L20+Summary!$C$22*M20+Summary!$C$23*N20+Summary!$C$24*O20+Summary!$C$25*P20+Summary!$C$26*Q20 -> 0 | X20: 1.00:0.00 | Y20: 77.60274 | Z20: 95
A21: 18 | B21: =1180-C21 -> -1690 | C21: =SUM(D21:J21) -> 2870 | D21: =D20-K21 -> 750 | E21: =E20-L21 -> 150 | F21: =F20-M21 -> 300 | G21: =G20-N21 -> 150 | H21: =H20-O21 -> 100 | I21: =I20-P21+550 -> 800 | J21: =J20-Q21 -> 620 | R21: E | T21: 95 | U21: 0 | V21: =SUM(K21:Q21) -> 0 | W21: =Summary!$C$20*K21+Summary!$C$21*L21+Summary!$C$22*M21+Summary!$C$23*N21+Summary!$C$24*O21+Summary!$C$25*P21+Summary!$C$26*Q21 -> 0 | X21: 1.00:0.00 | Y21: 95 | Z21: 95
A22: 19 | B22: =1180-C22 -> -1690 | C22: =SUM(D22:J22) -> 2870 | D22: =D21-K22 -> 750 | E22: =E21-L22 -> 150 | F22: =F21-M22 -> 300 | G22: =G21-N22 -> 150 | H22: =H21-O22 -> 100 | I22: =I21-P22 -> 800 | J22: =J21-Q22 -> 620 | R22: C | T22: 96 | U22: 0 | V22: =SUM(K22:Q22) -> 0 | W22: =Summary!$C$20*K22+Summary!$C$21*L22+Summary!$C$22*M22+Summary!$C$23*N22+Summary!$C$24*O22+Summary!$C$25*P22+Summary!$C$26*Q22 -> 0 | X22: 1.00:0.00 | Y22: 96 | Z22: 96
A23: 20 | B23: =1180-C23 -> -1690 | C23: =SUM(D23:J23) -> 2870 | D23: =D22-K23 -> 750 | E23: =E22-L23 -> 150 | F23: =F22-M23 -> 300 | G23: =G22-N23 -> 150 | H23: =H22-O23 -> 100 | I23: =I22-P23 -> 800 | J23: =J22-Q23 -> 620 | R23: C | T23: 96 | U23: 0 | V23: =SUM(K23:Q23) -> 0 | W23: =Summary!$C$20*K23+Summary!$C$21*L23+Summary!$C$22*M23+Summary!$C$23*N23+Summary!$C$24*O23+Summary!$C$25*P23+Summary!$C$26*Q23 -> 0 | X23: 1.00:0.00 | Y23: 96 | Z23: 96
A24: 21 | B24: =1180-C24 -> -1690 | C24: =SUM(D24:J24) -> 2870 | D24: =D23-K24 -> 750 | E24: =E23-L24 -> 150 | F24: =F23-M24 -> 300 | G24: =G23-N24 -> 150 | H24: =H23-O24 -> 100 | I24: =I23-P24 -> 800 | J24: =J23-Q24 -> 620 | R24: C | T24: 8 | U24: 0 | V24: =SUM(K24:Q24) -> 0 | W24: =Summary!$C$20*K24+Summary!$C$21*L24+Summary!$C$22*M24+Summary!$C$23*N24+Summary!$C$24*O24+Summary!$C$25*P24+Summary!$C$26*Q24 -> 0 | X24: 1.00:0.00 | Y24: 8 | Z24: 96
A25: 22 | B25: =1180-C25 -> -1690 | C25: =SUM(D25:J25) -> 2870 | D25: =D24-K25 -> 750 | E25: =E24-L25 -> 150 | F25: =F24-M25 -> 300 | G25: =G24-N25 -> 150 | H25: =H24-O25 -> 100 | I25: =I24-P25 -> 800 | J25: =J24-Q25 -> 620 | R25: Base | T25: 87 | U25: 0 | V25: =SUM(K25:Q25) -> 0 | W25: =Summary!$C$20*K25+Summary!$C$21*L25+Summary!$C$22*M25+Summary!$C$23*N25+Summary!$C$24*O25+Summary!$C$25*P25+Summary!$C$26*Q25 -> 0 | X25: 1.00:0.00 | Y25: 87 | Z25: 87
A26: 23 | B26: =1180-C26 -> -1690 | C26: =SUM(D26:J26) -> 2870 | D26: =D25-K26 -> 750 | E26: =E25-L26 -> 150 | F26: =F25-M26 -> 300 | G26: =G25-N26 -> 150 | H26: =H25-O26 -> 100 | I26: =I25-P26 -> 800 | J26: =J25-Q26 -> 620 | R26: Base | T26: 87 | U26: 0 | V26: =SUM(K26:Q26) -> 0 | W26: =Summary!$C$20*K26+Summary!$C$21*L26+Summary!$C$22*M26+Summary!$C$23*N26+Summary!$C$24*O26+Summary!$C$25*P26+Summary!$C$26*Q26 -> 0 | X26: 1.00:0.00 | Y26: 87 | Z26: 87
A27: 24 | B27: =1180-C27 -> -2250 | C27: =SUM(D27:J27) -> 3430 | D27: =D26-K27+360 -> 1110 | E27: =E26-L27 -> 150 | F27: =F26-M27 -> 300 | G27: =G26-N27+200 -> 350 | H27: =H26-O27 -> 100 | I27: =I26-P27 -> 800 | J27: =J26-Q27 -> 620 | R27: Base | T27: 87 | U27: 0 | V27: =SUM(K27:Q27) -> 0 | W27: =Summary!$C$20*K27+Summary!$C$21*L27+Summary!$C$22*M27+Summary!$C$23*N27+Summary!$C$24*O27+Summary!$C$25*P27+Summary!$C$26*Q27 -> 0 | X27: 1.00:0.00 | Y27: 87 | Z27: 87
A28: 25 | B28: =1180-C28 -> -2250 | C28: =SUM(D28:J28) -> 3430 | D28: =D27-K28 -> 1110 | E28: =E27-L28 -> 150 | F28: =F27-M28 -> 300 | G28: =G27-N28 -> 350 | H28: =H27-O28 -> 100 | I28: =I27-P28 -> 800 | J28: =J27-Q28 -> 620 | R28: Base | T28: 87 | U28: 0 | V28: =SUM(K28:Q28) -> 0 | W28: =Summary!$C$20*K28+Summary!$C$21*L28+Summary!$C$22*M28+Summary!$C$23*N28+Summary!$C$24*O28+Summary!$C$25*P28+Summary!$C$26*Q28 -> 0 | X28: 1.00:0.00 | Y28: 87 | Z28: 87
A29: 26 | B29: =1180-C29 -> -2250 | C29: =SUM(D29:J29) -> 3430 | D29: =D28-K29 -> 1110 | E29: =E28-L29 -> 150 | F29: =F28-M29 -> 300 | G29: =G28-N29 -> 350 | H29: =H28-O29 -> 100 | I29: =I28-P29 -> 800 | J29: =J28-Q29 -> 620 | R29: Base | T29: 12 | U29: 0 | V29: =SUM(K29:Q29) -> 0 | W29: =Summary!$C$20*K29+Summary!$C$21*L29+Summary!$C$22*M29+Summary!$C$23*N29+Summary!$C$24*O29+Summary!$C$25*P29+Summary!$C$26*Q29 -> 0 | X29: 1.00:0.00 | Y29: 12 | Z29: 87
A30: 27 | B30: =1180-C30 -> -2250 | C30: =SUM(D30:J30) -> 3430 | D30: =D29-K30 -> 1110 | E30: =E29-L30 -> 150 | F30: =F29-M30 -> 300 | G30: =G29-N30 -> 350 | H30: =H29-O30 -> 100 | I30: =I29-P30 -> 800 | J30: =J29-Q30 -> 620 | R30: D | T30: 95 | U30: 0 | V30: =SUM(K30:Q30) -> 0 | W30: =Summary!$C$20*K30+Summary!$C$21*L30+Summary!$C$22*M30+Summary!$C$23*N30+Summary!$C$24*O30+Summary!$C$25*P30+Summary!$C$26*Q30 -> 0 | X30: 1.00:0.00 | Y30: 95 | Z30: 95
A31: 28 | B31: =1180-C31 -> -2250 | C31: =SUM(D31:J31) -> 3430 | D31: =D30-K31 -> 1110 | E31: =E30-L31 -> 150 | F31: =F30-M31 -> 300 | G31: =G30-N31 -> 350 | H31: =H30-O31 -> 100 | I31: =I30-P31 -> 800 | J31: =J30-Q31 -> 620 | R31: D | T31: 55 | U31: 0 | V31: =SUM(K31:Q31) -> 0 | W31: =Summary!$C$20*K31+Summary!$C$21*L31+Summary!$C$22*M31+Summary!$C$23*N31+Summary!$C$24*O31+Summary!$C$25*P31+Summary!$C$26*Q31 -> 0 | X31: 1.00:0.00 | Y31: 55 | Z31: 95
A32: 29 | B32: =1180-C32 -> -2780 | C32: =SUM(D32:J32) -> 3960 | D32: =D31-K32 -> 1110 | E32: =E31-L32 -> 150 | F32: =F31-M32 -> 300 | G32: =G31-N32 -> 350 | H32: =H31-O32+150 -> 250 | I32: =I31-P32+100 -> 900 | J32: =J31-Q32+280 -> 900 | R32: E | T32: 95 | U32: 0 | V32: =SUM(K32:Q32) -> 0 | W32: =Summary!$C$20*K32+Summary!$C$21*L32+Summary!$C$22*M32+Summary!$C$23*N32+Summary!$C$24*O32+Summary!$C$25*P32+Summary!$C$26*Q32 -> 0 | X32: 1.00:0.00 | Y32: 95 | Z32: 95
A33: 30 | B33: =1180-C33 -> -2780 | C33: =SUM(D33:J33) -> 3960 | D33: =D32-K33 -> 1110 | E33: =E32-L33 -> 150 | F33: =F32-M33 -> 300 | G33: =G32-N33 -> 350 | H33: =H32-O33 -> 250 | I33: =I32-P33 -> 900 | J33: =J32-Q33 -> 900 | R33: E | T33: 95 | U33: 0 | V33: =SUM(K33:Q33) -> 0 | W33: =Summary!$C$20*K33+Summary!$C$21*L33+Summary!$C$22*M33+Summary!$C$23*N33+Summary!$C$24*O33+Summary!$C$25*P33+Summary!$C$26*Q33 -> 0 | X33: 1.00:0.00 | Y33: 95 | Z33: 95
A34: 31 | B34: =1180-C34 -> -2780 | C34: =SUM(D34:J34) -> 3960 | D34: =D33-K34 -> 1110 | E34: =E33-L34 -> 150 | F34: =F33-M34 -> 300 | G34: =G33-N34 -> 350 | H34: =H33-O34 -> 250 | I34: =I33-P34 -> 900 | J34: =J33-Q34 -> 900 | V34: =SUM(K34:Q34) -> 0 | W34: =Summary!$C$20*K34+Summary!$C$21*L34+Summary!$C$22*M34+Summary!$C$23*N34+Summary!$C$24*O34+Summary!$C$25*P34+Summary!$C$26*Q34 -> 0
A35: 32 | B35: =1180-C35 -> -2780 | C35: =SUM(D35:J35) -> 3960 | D35: =D34-K35 -> 1110 | E35: =E34-L35 -> 150 | F35: =F34-M35 -> 300 | G35: =G34-N35 -> 350 | H35: =H34-O35 -> 250 | I35: =I34-P35 -> 900 | J35: =J34-Q35 -> 900 | V35: =SUM(K35:Q35) -> 0 | W35: =Summary!$C$20*K35+Summary!$C$21*L35+Summary!$C$22*M35+Summary!$C$23*N35+Summary!$C$24*O35+Summary!$C$25*P35+Summary!$C$26*Q35 -> 0
A36: 33 | B36: =1180-C36 -> -2780 | C36: =SUM(D36:J36) -> 3960 | D36: =D35-K36 -> 1110 | E36: =E35-L36 -> 150 | F36: =F35-M36 -> 300 | G36: =G35-N36 -> 350 | H36: =H35-O36 -> 250 | I36: =I35-P36 -> 900 | J36: =J35-Q36 -> 900 | V36: =SUM(K36:Q36) -> 0 | W36: =Summary!$C$20*K36+Summary!$C$21*L36+Summary!$C$22*M36+Summary!$C$23*N36+Summary!$C$24*O36+Summary!$C$25*P36+Summary!$C$26*Q36 -> 0
A37: 34 | B37: =1180-C37 -> -2780 | C37: =SUM(D37:J37) -> 3960 | D37: =D36-K37 -> 1110 | E37: =E36-L37 -> 150 | F37: =F36-M37 -> 300 | G37: =G36-N37 -> 350 | H37: =H36-O37 -> 250 | I37: =I36-P37 -> 900 | J37: =J36-Q37 -> 900 | V37: =SUM(K37:Q37) -> 0 | W37: =Summary!$C$20*K37+Summary!$C$21*L37+Summary!$C$22*M37+Summary!$C$23*N37+Summary!$C$24*O37+Summary!$C$25*P37+Summary!$C$26*Q37 -> 0
A38: 35 | B38: =1180-C38 -> -2780 | C38: =SUM(D38:J38) -> 3960 | D38: =D37-K38 -> 1110 | E38: =E37-L38 -> 150 | F38: =F37-M38 -> 300 | G38: =G37-N38 -> 350 | H38: =H37-O38 -> 250 | I38: =I37-P38 -> 900 | J38: =J37-Q38 -> 900 | V38: =SUM(K38:Q38) -> 0 | W38: =Summary!$C$20*K38+Summary!$C$21*L38+Summary!$C$22*M38+Summary!$C$23*N38+Summary!$C$24*O38+Summary!$C$25*P38+Summary!$C$26*Q38 -> 0
A39: 36 | B39: =1180-C39 -> -2780 | C39: =SUM(D39:J39) -> 3960 | D39: =D38-K39 -> 1110 | E39: =E38-L39 -> 150 | F39: =F38-M39 -> 300 | G39: =G38-N39 -> 350 | H39: =H38-O39 -> 250 | I39: =I38-P39 -> 900 | J39: =J38-Q39 -> 900 | V39: =SUM(K39:Q39) -> 0 | W39: =Summary!$C$20*K39+Summary!$C$21*L39+Summary!$C$22*M39+Summary!$C$23*N39+Summary!$C$24*O39+Summary!$C$25*P39+Summary!$C$26*Q39 -> 0
A40: 37 | B40: =1180-C40 -> -2780 | C40: =SUM(D40:J40) -> 3960 | D40: =D39-K40 -> 1110 | E40: =E39-L40 -> 150 | F40: =F39-M40 -> 300 | G40: =G39-N40 -> 350 | H40: =H39-O40 -> 250 | I40: =I39-P40 -> 900 | J40: =J39-Q40 -> 900 | V40: =SUM(K40:Q40) -> 0 | W40: =Summary!$C$20*K40+Summary!$C$21*L40+Summary!$C$22*M40+Summary!$C$23*N40+Summary!$C$24*O40+Summary!$C$25*P40+Summary!$C$26*Q40 -> 0
...

Sheet Base Case (Working)
B1: All in KB | D1: Tapis | E1: Minas | F1: Jitang | G1: Sepat | H1: KIMC | I1: Kimanis | J1: Bintulu | K1: Tapis | L1: Minas | M1: Jitang | N1: Sepat | O1: KIMC | P1: Kimanis | Q1: Bintulu
A2: Day | B2: Ullage | C2: Processing Inventory | D2: Inventory_Base | E2: Inventory_A | F2: Inventory_B | G2: Inventory_C | H2: Inventory_D | I2: Inventory_E | J2: Inventory_F | K2: Rate_Base | L2: Rate_A | M2: Rate_B | N2: Rate_C | O2: Rate_D | P2: Rate_E | Q2: Rate_F | R2: primary_grade | S2: secondary_grade | T2: primary_rate | U2: secondary_rate | V2: total_rate | W2: Crude Margin (USD k) | X2: ratio | Y2: capacity_used | Z2: capacity_limit | AA2: Tank 1 | AB2: Tank 2 | AC2: Tank 3 | AD2: Tank 4 | AE2: Tank 5 | AF2: Delivery 1 | AG2: Delivery 2 | AH2: Delivery 3 | AI2: Delivery 4 | AJ2: Delivery 5 | AK2: Delivery 6 | AL2: Comment
A3: 0 | B3: =1180-C3 -> 393 | C3: =SUM(D3:J3) -> 787 | D3: =215+139 -> 354 | E3: 0 | F3: 0 | G3: 0 | H3: 0 | I3: 0 | J3: =51+286+96 -> 433 | K3: 0 | L3: 0 | M3: 0 | N3: 0 | O3: 0 | P3: 0 | Q3: 0 | V3: 0
A4: 1 | B4: =1180-C4 -> 158 | C4: =SUM(D4:J4) -> 1022 | D4: =D3-K4+160 -> 514 | E4: =E3-L4 -> 0 | F4: =F3-M4 -> 0 | G4: =G3-N4+170 -> 170 | H4: =H3-O4 -> 0 | I4: =I3-P4 -> 0 | J4: =J3-Q4 -> 338 | Q4: 95 | R4: C | S4: D | T4: 57.6 | U4: 38.4 | V4: =SUM(K4:Q4) -> 95 | W4: =Summary!$C$20*K4+Summary!$C$21*L4+Summary!$C$22*M4+Summary!$C$23*N4+Summary!$C$24*O4+Summary!$C$25*P4+Summary!$C$26*Q4 -> 947.15 | X4: 0.60:0.40 | Y4: 96 | Z4: 96 | AF4: Load Base (1-3)
A5: 2 | B5: =1180-C5 -> 253 | C5: =SUM(D5:J5) -> 927 | D5: =D4-K5 -> 514 | E5: =E4-L5 -> 0 | F5: =F4-M5 -> 0 | G5: =G4-N5 -> 170 | H5: =H4-O5 -> 0 | I5: =I4-P5 -> 0 | J5: =J4-Q5 -> 243 | Q5: 95 | R5: C | S5: D | T5: 57.6 | U5: 38.4 | V5: =SUM(K5:Q5) -> 95 | W5: =Summary!$C$20*K5+Summary!$C$21*L5+Summary!$C$22*M5+Summary!$C$23*N5+Summary!$C$24*O5+Summary!$C$25*P5+Summary!$C$26*Q5 -> 947.15 | X5: 0.60:0.40 | Y5: 96 | Z5: 96 | AF5: Load A (1-3)
A6: 3 | B6: =1180-C6 -> 348 | C6: =SUM(D6:J6) -> 832 | D6: =D5-K6 -> 514 | E6: =E5-L6 -> 0 | F6: =F5-M6 -> 0 | G6: =G5-N6 -> 170 | H6: =H5-O6 -> 0 | I6: =I5-P6 -> 0 | J6: =J5-Q6 -> 148 | Q6: 95 | R6: C | S6: D | T6: 34.8 | U6: 23.2 | V6: =SUM(K6:Q6) -> 95 | W6: =Summary!$C$20*K6+Summary!$C$21*L6+Summary!$C$22*M6+Summary!$C$23*N6+Summary!$C$24*O6+Summary!$C$25*P6+Summary!$C$26*Q6 -> 947.15 | X6: 0.60:0.40 | Y6: 58 | Z6: 96 | AF6: Sail
A7: 4 | B7: =1180-C7 -> 93 | C7: =SUM(D7:J7) -> 1087 | D7: =D6-K7 -> 514 | E7: =E6-L7 -> 0 | F7: =F6-M7 -> 0 | G7: =G6-N7 -> 170 | H7: =H6-O7 -> 0 | I7: =I6-P7+350 -> 350 | J7: =J6-Q7 -> 53 | Q7: 95 | R7: B | S7: Base | T7: 25.65 | U7: 69.35 | V7: =SUM(K7:Q7) -> 95 | W7: =Summary!$C$20*K7+Summary!$C$21*L7+Summary!$C$22*M7+Summary!$C$23*N7+Summary!$C$24*O7+Summary!$C$25*P7+Summary!$C$26*Q7 -> 947.15 | X7: 0.27:0.73 | Y7: 95 | Z7: 95 | AF7: Sail
A8: 5 | B8: =1180-C8 -> 188 | C8: =SUM(D8:J8) -> 992 | D8: =D7-K8 -> 484 | E8: =E7-L8 -> 0 | F8: =F7-M8 -> 0 | G8: =G7-N8 -> 158 | H8: =H7-O8 -> 0 | I8: =I7-P8 -> 350 | J8: =J7-Q8 -> 0 | K8: 30 | N8: 12 | Q8: 53 | R8: A | S8: Base | T8: 25.92 | U8: 70.08 | V8: =SUM(K8:Q8) -> 95 | W8: =Summary!$C$20*K8+Summary!$C$21*L8+Summary!$C$22*M8+Summary!$C$23*N8+Summary!$C$24*O8+Summary!$C$25*P8+Summary!$C$26*Q8 -> 1234.79 | X8: 0.27:0.73 | Y8: 96 | Z8: 96 | AF8: Discharge | AG8: Load E (5-7)
A9: 6 | B9: =1180-C9 -> 203 | C9: =SUM(D9:J9) -> 977 | D9: =D8-K9 -> 417 | E9: =E8-L9 -> 0 | F9: =F8-M9 -> 0 | G9: =G8-N9 -> 130 | H9: =H8-O9+80 -> 80 | I9: =I8-P9 -> 350 | J9: =J8-Q9 -> 0 | K9: 67 | N9: 28 | R9: A | S9: Base | T9: 25.92 | U9: 70.08 | V9: =SUM(K9:Q9) -> 95 | W9: =Summary!$C$20*K9+Summary!$C$21*L9+Summary!$C$22*M9+Summary!$C$23*N9+Summary!$C$24*O9+Summary!$C$25*P9+Summary!$C$26*Q9 -> 1600.67 | X9: 0.27:0.73 | Y9: 96 | Z9: 96 | AF9: Discharge | AG9: Sail to Sarawak
A10: 7 | B10: =1180-C10 -> 218 | C10: =SUM(D10:J10) -> 962 | D10: =D9-K10 -> 350 | E10: =E9-L10 -> 0 | F10: =F9-M10 -> 0 | G10: =G9-N10 -> 102 | H10: =H9-O10+80 -> 160 | I10: =I9-P10 -> 350 | J10: =J9-Q10 -> 0 | K10: 67 | N10: 28 | R10: A | S10: Base | T10: 25.92 | U10: 70.08 | V10: =SUM(K10:Q10) -> 95 | W10: =Summary!$C$20*K10+Summary!$C$21*L10+Summary!$C$22*M10+Summary!$C$23*N10+Summary!$C$24*O10+Summary!$C$25*P10+Summary!$C$26*Q10 -> 1600.67 | X10: 0.27:0.73 | Y10: 96 | Z10: 96 | AF10: Tk prep | AG10: Load F (5-7)
A11: 8 | B11: =1180-C11 -> 313 | C11: =SUM(D11:J11) -> 867 | D11: =D10-K11 -> 283 | E11: =E10-L11 -> 0 | F11: =F10-M11 -> 0 | G11: =G10-N11 -> 74 | H11: =H10-O11 -> 160 | I11: =I10-P11 -> 350 | J11: =J10-Q11 -> 0 | K11: 67 | N11: 28 | R11: A | S11: Base | T11: 25.92 | U11: 70.08 | V11: =SUM(K11:Q11) -> 95 | W11: =Summary!$C$20*K11+Summary!$C$21*L11+Summary!$C$22*M11+Summary!$C$23*N11+Summary!$C$24*O11+Summary!$C$25*P11+Summary!$C$26*Q11 -> 1600.67 | X11: 0.27:0.73 | Y11: 96 | Z11: 96 | AF11: Tk prep | AG11: Sail
A12: 9 | B12: =1180-C12 -> 158 | C12: =SUM(D12:J12) -> 1022 | D12: =D11-K12 -> 216 | E12: =E11-L12 -> 0 | F12: =F11-M12 -> 0 | G12: =G11-N12 -> 46 | H12: =H11-O12 -> 160 | I12: =I11-P12+250 -> 600 | J12: =J11-Q12 -> 0 | K12: 67 | N12: 28 | R12: A | S12: Base | T12: 25.92 | U12: 70.08 | V12: =SUM(K12:Q12) -> 95 | W12: =Summary!$C$20*K12+Summary!$C$21*L12+Summary!$C$22*M12+Summary!$C$23*N12+Summary!$C$24*O12+Summary!$C$25*P12+Summary!$C$26*Q12 -> 1600.67 | X12: 0.27:0.73 | Y12: 96 | Z12: 96 | AF12: Tk prep | AG12: Sail
A13: 10 | B13: =1180-C13 -> 253 | C13: =SUM(D13:J13) -> 927 | D13: =D12-K13 -> 149 | E13: =E12-L13 -> 0 | F13: =F12-M13 -> 0 | G13: =G12-N13 -> 18 | H13: =H12-O13 -> 160 | I13: =I12-P13 -> 600 | J13: =J12-Q13 -> 0 | K13: 67 | N13: 28 | R13: A | S13: Base | T13: 20.4 | U13: 55.155556 | V13: =SUM(K13:Q13) -> 95 | W13: =Summary!$C$20*K13+Summary!$C$21*L13+Summary!$C$22*M13+Summary!$C$23*N13+Summary!$C$24*O13+Summary!$C$25*P13+Summary!$C$26*Q13 -> 1600.67 | X13: 0.27:0.73 | Y13: 75.555556 | Z13: 96 | AF13: Base: 400, A :150 | AG13: Sail | AH13: Load B (8-10)
A14: 11 | B14: =1180-C14 -> 348 | C14: =SUM(D14:J14) -> 832 | D14: =D13-K14 -> 106 | E14: =E13-L14 -> 0 | F14: =F13-M14 -> 0 | G14: =G13-N14 -> 0 | H14: =H13-O14 -> 160 | I14: =I13-P14 -> 566 | J14: =J13-Q14 -> 0 | K14: 43 | N14: 18 | P14: 34 | R14: B | S14: Base | T14: 25.65 | U14: 69.35 | V14: =SUM(K14:Q14) -> 95 | W14: =Summary!$C$20*K14+Summary!$C$21*L14+Summary!$C$22*M14+Summary!$C$23*N14+Summary!$C$24*O14+Summary!$C$25*P14+Summary!$C$26*Q14 -> 1367.19 | X14: 0.27:0.73 | Y14: 95 | Z14: 95 | AG14: Discharge | AH14: Sail | AI14: Load E (10-11)
A15: 12 | B15: =1180-C15 -> 143 | C15: =SUM(D15:J15) -> 1037 | D15: =D14-K15 -> 106 | E15: =E14-L15 -> 0 | F15: =F14-M15 -> 0 | G15: =G14-N15 -> 0 | H15: =H14-O15 -> 160 | I15: =I14-P15 -> 471 | J15: =J14-Q15+300 -> 300 | P15: 95 | R15: B | S15: Base | T15: 25.65 | U15: 69.35 | V15: =SUM(K15:Q15) -> 95 | W15: =Summary!$C$20*K15+Summary!$C$21*L15+Summary!$C$22*M15+Summary!$C$23*N15+Summary!$C$24*O15+Summary!$C$25*P15+Summary!$C$26*Q15 -> 948.1 | X15: 0.27:0.73 | Y15: 95 | Z15: 95 | AG15: Discharge | AH15: Sail | AI15: Sail
A16: 13 | B16: =1180-C16 -> 238 | C16: =SUM(D16:J16) -> 942 | D16: =D15-K16 -> 106 | E16: =E15-L16 -> 0 | F16: =F15-M16 -> 0 | G16: =G15-N16 -> 0 | H16: =H15-O16 -> 160 | I16: =I15-P16 -> 376 | J16: =J15-Q16 -> 300 | P16: 95 | R16: B | S16: Base | T16: 25.65 | U16: 69.35 | V16: =SUM(K16:Q16) -> 95 | W16: =Summary!$C$20*K16+Summary!$C$21*L16+Summary!$C$22*M16+Summary!$C$23*N16+Summary!$C$24*O16+Summary!$C$25*P16+Summary!$C$26*Q16 -> 948.1 | X16: 0.27:0.73 | Y16: 95 | Z16: 95 | AG16: Tank Prep | AH16: Discharge | AI16: Sail
A17: 14 | B17: =1180-C17 -> 143 | C17: =SUM(D17:J17) -> 1037 | D17: =D16-K17 -> 106 | E17: =E16-L17+190 -> 190 | F17: =F16-M17 -> 0 | G17: =G16-N17 -> 0 | H17: =H16-O17 -> 160 | I17: =I16-P17 -> 281 | J17: =J16-Q17 -> 300 | P17: 95 | R17: B | S17: Base | T17: 24.79726 | U17: 67.044444 | V17: =SUM(K17:Q17) -> 95 | W17: =Summary!$C$20*K17+Summary!$C$21*L17+Summary!$C$22*M17+Summary!$C$23*N17+Summary!$C$24*O17+Summary!$C$25*P17+Summary!$C$26*Q17 -> 948.1 | X17: 0.27:0.73 | Y17: 91.841705 | Z17: 95 | AG17: Tank Prep | AH17: Discharge | AI17: Sail
A18: 15 | B18: =1180-C18 -> 238 | C18: =SUM(D18:J18) -> 942 | D18: =D17-K18 -> 106 | E18: =E17-L18 -> 190 | F18: =F17-M18 -> 0 | G18: =G17-N18 -> 0 | H18: =H17-O18 -> 160 | I18: =I17-P18 -> 186 | J18: =J17-Q18 -> 300 | P18: 95 | R18: C | T18: 7.1054274e-15 | U18: 0 | V18: =SUM(K18:Q18) -> 95 | W18: =Summary!$C$20*K18+Summary!$C$21*L18+Summary!$C$22*M18+Summary!$C$23*N18+Summary!$C$24*O18+Summary!$C$25*P18+Summary!$C$26*Q18 -> 948.1 | X18: 1.00:0.00 | Y18: 7.1054274e-15 | Z18: 96 | AG18: Tank Prep | AH18: Tank Prep | AI18: Demurrage
A19: 16 | B19: =1180-C19 -> 333 | C19: =SUM(D19:J19) -> 847 | D19: =D18-K19 -> 106 | E19: =E18-L19 -> 190 | F19: =F18-M19 -> 0 | G19: =G18-N19 -> 0 | H19: =H18-O19 -> 160 | I19: =I18-P19 -> 91 | J19: =J18-Q19 -> 300 | P19: 95 | R19: B | T19: 95 | U19: 0 | V19: =SUM(K19:Q19) -> 95 | W19: =Summary!$C$20*K19+Summary!$C$21*L19+Summary!$C$22*M19+Summary!$C$23*N19+Summary!$C$24*O19+Summary!$C$25*P19+Summary!$C$26*Q19 -> 948.1 | X19: 1.00:0.00 | Y19: 95 | Z19: 95 | AG19: E: 250, F: 320 | AH19: Tank Prep | AI19: Demurrage
A20: 17 | B20: =1180-C20 -> 118 | C20: =SUM(D20:J20) -> 1062 | D20: =D19-K20+310 -> 416 | E20: =E19-L20 -> 190 | F20: =F19-M20 -> 0 | G20: =G19-N20 -> 0 | H20: =H19-O20 -> 160 | I20: =I19-P20 -> 0 | J20: =J19-Q20 -> 296 | P20: 91 | Q20: 4 | R20: B | T20: 77.60274 | U20: 0 | V20: =SUM(K20:Q20) -> 95 | W20: =Summary!$C$20*K20+Summary!$C$21*L20+Summary!$C$22*M20+Summary!$C$23*N20+Summary!$C$24*O20+Summary!$C$25*P20+Summary!$C$26*Q20 -> 948.06 | X20: 1.00:0.00 | Y20: 77.60274 | Z20: 95 | AH20: Tank Prep | AI20: Discharge
A21: 18 | B21: =1180-C21 -> 213 | C21: =SUM(D21:J21) -> 967 | D21: =D20-K21 -> 416 | E21: =E20-L21 -> 190 | F21: =F20-M21 -> 0 | G21: =G20-N21 -> 0 | H21: =H20-O21 -> 160 | I21: =I20-P21 -> 0 | J21: =J20-Q21 -> 201 | Q21: 95 | R21: E | T21: 95 | U21: 0 | V21: =SUM(K21:Q21) -> 95 | W21: =Summary!$C$20*K21+Summary!$C$21*L21+Summary!$C$22*M21+Summary!$C$23*N21+Summary!$C$24*O21+Summary!$C$25*P21+Summary!$C$26*Q21 -> 947.15 | X21: 1.00:0.00 | Y21: 95 | Z21: 95 | AH21: B: 150 | AI21: Discharge | AJ21: Load Base (17-19)
A22: 19 | B22: =1180-C22 -> 308 | C22: =SUM(D22:J22) -> 872 | D22: =D21-K22 -> 416 | E22: =E21-L22 -> 190 | F22: =F21-M22 -> 0 | G22: =G21-N22 -> 0 | H22: =H21-O22 -> 160 | I22: =I21-P22 -> 0 | J22: =J21-Q22 -> 106 | Q22: 95 | R22: C | T22: 96 | U22: 0 | V22: =SUM(K22:Q22) -> 95 | W22: =Summary!$C$20*K22+Summary!$C$21*L22+Summary!$C$22*M22+Summary!$C$23*N22+Summary!$C$24*O22+Summary!$C$25*P22+Summary!$C$26*Q22 -> 947.15 | X22: 1.00:0.00 | Y22: 96 | Z22: 96 | AI22: Tank Prep | AJ22: Load C (17-19)
A23: 20 | B23: =1180-C23 -> 401 | C23: =SUM(D23:J23) -> 779 | D23: =D22-K23 -> 365 | E23: =E22-L23 -> 169 | F23: =F22-M23 -> 0 | G23: =G22-N23 -> 0 | H23: =H22-O23 -> 160 | I23: =I22-P23 -> 0 | J23: =J22-Q23 -> 85 | K23: 51 | L23: 21 | Q23: 21 | R23: C | T23: 96 | U23: 0 | V23: =SUM(K23:Q23) -> 93 | W23: =Summary!$C$20*K23+Summary!$C$21*L23+Summary!$C$22*M23+Summary!$C$23*N23+Summary!$C$24*O23+Summary!$C$25*P23+Summary!$C$26*Q23 -> 1405.59 | X23: 1.00:0.00 | Y23: 96 | Z23: 96 | AI23: Tank Prep | AJ23: Sail
A24: 21 | B24: =1180-C24 -> 141 | C24: =SUM(D24:J24) -> 1039 | D24: =D23-K24 -> 301 | E24: =E23-L24 -> 143 | F24: =F23-M24 -> 0 | G24: =G23-N24 -> 0 | H24: =H23-O24 -> 160 | I24: =I23-P24+50 -> 50 | J24: =J23-Q24+300 -> 385 | K24: 64 | L24: 26 | R24: C | T24: 8 | U24: 0 | V24: =SUM(K24:Q24) -> 90 | W24: =Summary!$C$20*K24+Summary!$C$21*L24+Summary!$C$22*M24+Summary!$C$23*N24+Summary!$C$24*O24+Summary!$C$25*P24+Summary!$C$26*Q24 -> 1494.62 | X24: 1.00:0.00 | Y24: 8 | Z24: 96 | AI24: Tank Prep | AJ24: Sail | AK24: Load F (19-22)
A25: 22 | B25: =1180-C25 -> 231 | C25: =SUM(D25:J25) -> 949 | D25: =D24-K25 -> 237 | E25: =E24-L25 -> 117 | F25: =F24-M25 -> 0 | G25: =G24-N25 -> 0 | H25: =H24-O25 -> 160 | I25: =I24-P25 -> 50 | J25: =J24-Q25 -> 385 | K25: 64 | L25: 26 | R25: Base | T25: 87 | U25: 0 | V25: =SUM(K25:Q25) -> 90 | W25: =Summary!$C$20*K25+Summary!$C$21*L25+Summary!$C$22*M25+Summary!$C$23*N25+Summary!$C$24*O25+Summary!$C$25*P25+Summary!$C$26*Q25 -> 1494.62 | X25: 1.00:0.00 | Y25: 87 | Z25: 87 | AI25: E: 550 | AJ25: Demurrage | AK25: Sail to Sabah
A26: 23 | B26: =1180-C26 -> 321 | C26: =SUM(D26:J26) -> 859 | D26: =D25-K26 -> 173 | E26: =E25-L26 -> 91 | F26: =F25-M26 -> 0 | G26: =G25-N26 -> 0 | H26: =H25-O26 -> 160 | I26: =I25-P26 -> 50 | J26: =J25-Q26 -> 385 | K26: 64 | L26: 26 | R26: Base | T26: 87 | U26: 0 | V26: =SUM(K26:Q26) -> 90 | W26: =Summary!$C$20*K26+Summary!$C$21*L26+Summary!$C$22*M26+Summary!$C$23*N26+Summary!$C$24*O26+Summary!$C$25*P26+Summary!$C$26*Q26 -> 1494.62 | X26: 1.00:0.00 | Y26: 87 | Z26: 87 | AJ26: Discharge | AK26: Load E (23-24)
A27: 24 | B27: =1180-C27 -> 161 | C27: =SUM(D27:J27) -> 1019 | D27: =D26-K27+250 -> 359 | E27: =E26-L27 -> 65 | F27: =F26-M27 -> 0 | G27: =G26-N27 -> 0 | H27: =H26-O27 -> 160 | I27: =I26-P27 -> 50 | J27: =J26-Q27 -> 385 | K27: 64 | L27: 26 | R27: Base | T27: 87 | U27: 0 | V27: =SUM(K27:Q27) -> 90 | W27: =Summary!$C$20*K27+Summary!$C$21*L27+Summary!$C$22*M27+Summary!$C$23*N27+Summary!$C$24*O27+Summary!$C$25*P27+Summary!$C$26*Q27 -> 1494.62 | X27: 1.00:0.00 | Y27: 87 | Z27: 87 | AJ27: Discharge | AK27: Load D (23-24)
A28: 25 | B28: =1180-C28 -> 251 | C28: =SUM(D28:J28) -> 929 | D28: =D27-K28 -> 295 | E28: =E27-L28 -> 39 | F28: =F27-M28 -> 0 | G28: =G27-N28 -> 0 | H28: =H27-O28 -> 160 | I28: =I27-P28 -> 50 | J28: =J27-Q28 -> 385 | K28: 64 | L28: 26 | R28: Base | T28: 87 | U28: 0 | V28: =SUM(K28:Q28) -> 90 | W28: =Summary!$C$20*K28+Summary!$C$21*L28+Summary!$C$22*M28+Summary!$C$23*N28+Summary!$C$24*O28+Summary!$C$25*P28+Summary!$C$26*Q28 -> 1494.62 | X28: 1.00:0.00 | Y28: 87 | Z28: 87 | AJ28: Tank Prep | AK28: Sail
A29: 26 | B29: =1180-C29 -> 341 | C29: =SUM(D29:J29) -> 839 | D29: =D28-K29 -> 231 | E29: =E28-L29 -> 13 | F29: =F28-M29 -> 0 | G29: =G28-N29 -> 0 | H29: =H28-O29 -> 160 | I29: =I28-P29 -> 50 | J29: =J28-Q29 -> 385 | K29: 64 | L29: 26 | R29: Base | T29: 12 | U29: 0 | V29: =SUM(K29:Q29) -> 90 | W29: =Summary!$C$20*K29+Summary!$C$21*L29+Summary!$C$22*M29+Summary!$C$23*N29+Summary!$C$24*O29+Summary!$C$25*P29+Summary!$C$26*Q29 -> 1494.62 | X29: 1.00:0.00 | Y29: 12 | Z29: 87 | AJ29: Tank Prep | AK29: Sail
A30: 27 | B30: =1180-C30 -> 274 | C30: =SUM(D30:J30) -> 906 | D30: =D29-K30+160 -> 359 | E30: =E29-L30 -> 0 | F30: =F29-M30 -> 0 | G30: =G29-N30 -> 0 | H30: =H29-O30 -> 160 | I30: =I29-P30 -> 30 | J30: =J29-Q30 -> 357 | K30: 32 | L30: 13 | P30: 20 | Q30: 28 | R30: D | T30: 95 | U30: 0 | V30: =SUM(K30:Q30) -> 93 | W30: =Summary!$C$20*K30+Summary!$C$21*L30+Summary!$C$22*M30+Summary!$C$23*N30+Summary!$C$24*O30+Summary!$C$25*P30+Summary!$C$26*Q30 -> 1226.07 | X30: 1.00:0.00 | Y30: 95 | Z30: 95 | AJ30: Tank Prep | AK30: Sail
A31: 28 | B31: =1180-C31 -> 369 | C31: =SUM(D31:J31) -> 811 | D31: =D30-K31 -> 359 | E31: =E30-L31 -> 0 | F31: =F30-M31 -> 0 | G31: =G30-N31 -> 0 | H31: =H30-O31 -> 160 | I31: =I30-P31 -> 10 | J31: =J30-Q31 -> 282 | P31: 20 | Q31: 75 | R31: D | T31: 55 | U31: 0 | V31: =SUM(K31:Q31) -> 95 | W31: =Summary!$C$20*K31+Summary!$C$21*L31+Summary!$C$22*M31+Summary!$C$23*N31+Summary!$C$24*O31+Summary!$C$25*P31+Summary!$C$26*Q31 -> 947.35 | X31: 1.00:0.00 | Y31: 55 | Z31: 95 | AJ31: Base: 360, C: 200 | AK31: Discharge
A32: 29 | B32: =1180-C32 -> 164 | C32: =SUM(D32:J32) -> 1016 | D32: =D31-K32 -> 359 | E32: =E31-L32 -> 0 | F32: =F31-M32 -> 0 | G32: =G31-N32 -> 0 | H32: =H31-O32 -> 160 | I32: =I31-P32 -> 0 | J32: =J31-Q32+300 -> 497 | P32: 10 | Q32: 85 | R32: E | T32: 95 | U32: 0 | V32: =SUM(K32:Q32) -> 95 | W32: =Summary!$C$20*K32+Summary!$C$21*L32+Summary!$C$22*M32+Summary!$C$23*N32+Summary!$C$24*O32+Summary!$C$25*P32+Summary!$C$26*Q32 -> 947.25 | X32: 1.00:0.00 | Y32: 95 | Z32: 95 | AK32: Discharge
A33: 30 | B33: =1180-C33 -> 259 | C33: =SUM(D33:J33) -> 921 | D33: =D32-K33 -> 359 | E33: =E32-L33 -> 0 | F33: =F32-M33 -> 0 | G33: =G32-N33 -> 0 | H33: =H32-O33 -> 160 | I33: =I32-P33 -> 0 | J33: =J32-Q33 -> 402 | Q33: 95 | R33: E | T33: 95 | U33: 0 | V33: =SUM(K33:Q33) -> 95 | W33: =Summary!$C$20*K33+Summary!$C$21*L33+Summary!$C$22*M33+Summary!$C$23*N33+Summary!$C$24*O33+Summary!$C$25*P33+Summary!$C$26*Q33 -> 947.15 | X33: 1.00:0.00 | Y33: 95 | Z33: 95 | AK33: Tank Prep
A34: 31 | B34: =1180-C34 -> 354 | C34: =SUM(D34:J34) -> 826 | D34: =D33-K34 -> 359 | E34: =E33-L34 -> 0 | F34: =F33-M34 -> 0 | G34: =G33-N34 -> 0 | H34: =H33-O34 -> 160 | I34: =I33-P34 -> 0 | J34: =J33-Q34 -> 307 | Q34: 95 | V34: =SUM(K34:Q34) -> 95 | W34: =Summary!$C$20*K34+Summary!$C$21*L34+Summary!$C$22*M34+Summary!$C$23*N34+Summary!$C$24*O34+Summary!$C$25*P34+Summary!$C$26*Q34 -> 947.15 | AK34: Tank Prep
A35: 1 | B35: =1180-C35 -> 266 | C35: =SUM(D35:J35) -> 914 | D35: =D34-K35 -> 274 | E35: =E34-L35 -> 0 | F35: =F34-M35 -> 0 | G35: =G34-N35+180 -> 180 | H35: =H34-O35 -> 160 | I35: =I34-P35 -> 0 | J35: =J34-Q35 -> 300 | K35: 85 | Q35: 7 | V35: =SUM(K35:Q35) -> 92 | W35: =Summary!$C$20*K35+Summary!$C$21*L35+Summary!$C$22*M35+Summary!$C$23*N35+Summary!$C$24*O35+Summary!$C$25*P35+Summary!$C$26*Q35 -> 1417.04 | AK35: Tank Prep
A36: 2 | B36: =1180-C36 -> 351 | C36: =SUM(D36:J36) -> 829 | D36: =D35-K36 -> 189 | E36: =E35-L36 -> 0 | F36: =F35-M36 -> 0 | G36: =G35-N36 -> 180 | H36: =H35-O36 -> 160 | I36: =I35-P36 -> 0 | J36: =J35-Q36 -> 300 | K36: 85 | V36: =SUM(K36:Q36) -> 85 | W36: =Summary!$C$20*K36+Summary!$C$21*L36+Summary!$C$22*M36+Summary!$C$23*N36+Summary!$C$24*O36+Summary!$C$25*P36+Summary!$C$26*Q36 -> 1347.25 | AK36: F: 280, E: 100, D: 150
A37: 3 | B37: =1180-C37 -> 261 | C37: =SUM(D37:J37) -> 919 | D37: =D36-K37+175 -> 279 | E37: =E36-L37 -> 0 | F37: =F36-M37 -> 0 | G37: =G36-N37 -> 180 | H37: =H36-O37 -> 160 | I37: =I36-P37 -> 0 | J37: =J36-Q37 -> 300 | K37: 85 | V37: =SUM(K37:Q37) -> 85 | W37: =Summary!$C$20*K37+Summary!$C$21*L37+Summary!$C$22*M37+Summary!$C$23*N37+Summary!$C$24*O37+Summary!$C$25*P37+Summary!$C$26*Q37 -> 1347.25
A38: 4 | B38: =1180-C38 -> 346 | C38: =SUM(D38:J38) -> 834 | D38: =D37-K38 -> 194 | E38: =E37-L38 -> 0 | F38: =F37-M38 -> 0 | G38: =G37-N38 -> 180 | H38: =H37-O38 -> 160 | I38: =I37-P38 -> 0 | J38: =J37-Q38 -> 300 | K38: 85 | V38: =SUM(K38:Q38) -> 85 | W38: =Summary!$C$20*K38+Summary!$C$21*L38+Summary!$C$22*M38+Summary!$C$23*N38+Summary!$C$24*O38+Summary!$C$25*P38+Summary!$C$26*Q38 -> 1347.25
A39: 5 | B39: =1180-C39 -> 141 | C39: =SUM(D39:J39) -> 1039 | D39: =D38-K39 -> 194 | E39: =E38-L39 -> 0 | F39: =F38-M39 -> 0 | G39: =G38-N39 -> 180 | H39: =H38-O39 -> 160 | I39: =I38-P39+300 -> 300 | J39: =J38-Q39 -> 205 | Q39: 95 | V39: =SUM(K39:Q39) -> 95 | W39: =Summary!$C$20*K39+Summary!$C$21*L39+Summary!$C$22*M39+Summary!$C$23*N39+Summary!$C$24*O39+Summary!$C$25*P39+Summary!$C$26*Q39 -> 947.15
A40: 6 | B40: =1180-C40 -> 236 | C40: =SUM(D40:J40) -> 944 | D40: =D39-K40 -> 194 | E40: =E39-L40 -> 0 | F40: =F39-M40 -> 0 | G40: =G39-N40 -> 180 | H40: =H39-O40 -> 160 | I40: =I39-P40 -> 300 | J40: =J39-Q40 -> 110 | Q40: 95 | V40: =SUM(K40:Q40) -> 95 | W40: =Summary!$C$20*K40+Summary!$C$21*L40+Summary!$C$22*M40+Summary!$C$23*N40+Summary!$C$24*O40+Summary!$C$25*P40+Summary!$C$26*Q40 -> 947.15
...

Sheet Base Case (Celebal)
B1: All in KB | F1: Tapis | G1: Dulang | H1: Jitang | I1: Sepat | J1: KIMC | K1: Kimanis | L1: Bintulu
A2: Day | B2: Ullage | C2: Demurrage (day) | D2: Crude Discharge | E2: Processing Inventory | F2: Inventory_Base | G2: Inventory_A | H2: Inventory_B | I2: Inventory_C | J2: Inventory_D | K2: Inventory_E | L2: Inventory_F | M2: Rate_Base | N2: Rate_A | O2: Rate_B | P2: Rate_C | Q2: Rate_D | R2: Rate_E | S2: Rate_F | T2: primary_grade | U2: secondary_grade | V2: primary_rate | W2: secondary_rate | X2: total_rate | Y2: ratio | Z2: capacity_used | AA2: capacity_limit | AB2: Tank 1 | AC2: Tank 2 | AD2: Tank 3 | AE2: Tank 4 | AF2: Tank 5 | AG2: Delivery 1 | AH2: Delivery 2 | AI2: Delivery 3 | AJ2: Delivery 4 | AK2: Delivery 5 | AL2: Delivery 6 | AM2: Comment
A3: 0 | B3: =1180-E3 -> 130 | E3: =SUM(F3:L3) -> 1050 | F3: 350 | G3: 0 | H3: 150 | I3: 150 | J3: 100 | K3: 0 | L3: 300 | M3: 0 | N3: 0 | O3: 0 | P3: 0 | Q3: 0 | R3: 0 | S3: 0 | X3: 0
A4: 1 | B4: =1180-E4 -> 130 | E4: =SUM(F4:L4) -> 1050 | F4: =F3-M3 -> 350 | G4: 0 | H4: 150 | I4: =I3-P3 -> 150 | J4: 100 | K4: 0 | L4: 300 | M4: =95*0.73 -> 69.35 | N4: 0 | O4: 0 | P4: =95*0.27 -> 25.65 | Q4: 0 | R4: 0 | S4: 0 | T4: C | U4: D | V4: 57.6 | W4: 38.4 | X4: =SUM(M4:S4) -> 95 | Y4: 0.60:0.40 | Z4: 96 | AA4: 96 | AG4: Load Base (1-3)
A5: 2 | B5: =1180-E5 -> 225 | E5: =SUM(F5:L5) -> 955 | F5: =F4-M4 -> 280.65 | G5: =G4-N4 -> 0 | H5: =H4-O4 -> 150 | I5: =I4-P4 -> 124.35 | J5: =J4-Q4 -> 100 | K5: =K4-R4 -> 0 | L5: =L4-S4 -> 300 | M5: =95*0.73 -> 69.35 | N5: 0 | O5: 0 | P5: =95*0.27 -> 25.65 | Q5: 0 | R5: 0 | S5: 0 | T5: C | U5: D | V5: 57.6 | W5: 38.4 | X5: =SUM(M5:S5) -> 95 | Y5: 0.60:0.40 | Z5: 96 | AA5: 96 | AG5: Load A (1-3)
A6: 3 | B6: =1180-E6 -> 320 | E6: =SUM(F6:L6) -> 860 | F6: =F5-M5 -> 211.3 | G6: =G5-N5 -> 0 | H6: =H5-O5 -> 150 | I6: =I5-P5 -> 98.7 | J6: =J5-Q5 -> 100 | K6: =K5-R5 -> 0 | L6: =L5-S5 -> 300 | M6: =95*0.73 -> 69.35 | N6: 0 | O6: 0 | P6: =95*0.27 -> 25.65 | Q6: 0 | R6: 0 | S6: 0 | T6: C | U6: D | V6: 34.8 | W6: 23.2 | X6: =SUM(M6:S6) -> 95 | Y6: 0.60:0.40 | Z6: 58 | AA6: 96 | AG6: Sail
A7: 4 | B7: =1180-E7 -> 415 | E7: =SUM(F7:L7) -> 765 | F7: =F6-M6 -> 141.95 | G7: =G6-N6 -> 0 | H7: =H6-O6 -> 150 | I7: =I6-P6 -> 73.05 | J7: =J6-Q6 -> 100 | K7: =K6-R6 -> 0 | L7: =L6-S6 -> 300 | M7: =95*0.73 -> 69.35 | N7: 0 | O7: 0 | P7: =95*0.27 -> 25.65 | Q7: 0 | R7: 0 | S7: 0 | T7: B | U7: Base | V7: 25.65 | W7: 69.35 | X7: =SUM(M7:S7) -> 95 | Y7: 0.27:0.73 | Z7: 95 | AA7: 95 | AG7: Sail
A8: 5 | B8: =1180-E8 -> 510 | E8: =SUM(F8:L8) -> 670 | F8: =F7-M7 -> 72.6 | G8: =G7-N7 -> 0 | H8: =H7-O7 -> 150 | I8: =I7-P7 -> 47.4 | J8: =J7-Q7 -> 100 | K8: =K7-R7 -> 0 | L8: =L7-S7 -> 300 | M8: =95*0.73 -> 69.35 | N8: 0 | O8: 0 | P8: =95*0.27 -> 25.65 | Q8: 0 | R8: 0 | S8: 0 | T8: A | U8: Base | V8: 25.92 | W8: 70.08 | X8: =SUM(M8:S8) -> 95 | Y8: 0.27:0.73 | Z8: 96 | AA8: 96 | AG8: Discharge | AH8: Load E (5-7)
A9: 6 | B9: =1180-E9 -> 55 | D9: 400Base+150A | E9: =SUM(F9:L9) -> 1125 | F9: =F8-M8+400 -> 403.25 | G9: =G8-N8+150 -> 150 | H9: =H8-O8 -> 150 | I9: =I8-P8 -> 21.75 | J9: =J8-Q8 -> 100 | K9: =K8-R8 -> 0 | L9: =L8-S8 -> 300 | M9: 0 | N9: 0 | O9: 0 | P9: 0 | Q9: 0 | R9: 0 | S9: 95 | T9: A | U9: Base | V9: 25.92 | W9: 70.08 | X9: =SUM(M9:S9) -> 95 | Y9: 0.27:0.73 | Z9: 96 | AA9: 96 | AG9: Discharge | AH9: Sail to PM
A10: 7 | B10: =1180-E10 -> 150 | E10: =SUM(F10:L10) -> 1030 | F10: =F9-M9 -> 403.25 | G10: =G9-N9 -> 150 | H10: =H9-O9 -> 150 | I10: =I9-P9 -> 21.75 | J10: =J9-Q9 -> 100 | K10: =K9-R9 -> 0 | L10: =L9-S9 -> 205 | M10: 0 | N10: 0 | O10: 0 | P10: 0 | Q10: 0 | R10: 0 | S10: 95 | T10: A | U10: Base | V10: 25.92 | W10: 70.08 | X10: =SUM(M10:S10) -> 95 | Y10: 0.27:0.73 | Z10: 96 | AA10: 96 | AG10: Tank Prep | AH10: Sail to PM | AI10: Load B (8-10)
A11: 8 | B11: =1180-E11 -> 245 | E11: =SUM(F11:L11) -> 935 | F11: =F10-M10 -> 403.25 | G11: =G10-N10 -> 150 | H11: =H10-O10 -> 150 | I11: =I10-P10 -> 21.75 | J11: =J10-Q10 -> 100 | K11: =K10-R10 -> 0 | L11: =L10-S10 -> 110 | M11: 0 | N11: 0 | O11: 0 | P11: 0 | Q11: 0 | R11: 0 | S11: 95 | T11: A | U11: Base | V11: 25.92 | W11: 70.08 | X11: =SUM(M11:S11) -> 95 | Y11: 0.27:0.73 | Z11: 96 | AA11: 96 | AG11: Tank Prep | AH11: Sail to PM | AI11: Sail to Melaka
A12: 9 | B12: =1180-E12 -> 340 | E12: =SUM(F12:L12) -> 840 | F12: =F11-M11 -> 403.25 | G12: =G11-N11 -> 150 | H12: =H11-O11 -> 150 | I12: =I11-P11 -> 21.75 | J12: =J11-Q11 -> 100 | K12: =K11-R11 -> 0 | L12: =L11-S11 -> 15 | M12: 0 | N12: 0 | O12: =(95-S12)*0.6 -> 48 | P12: 0 | Q12: =(95-S12)*0.4 -> 32 | R12: 0 | S12: =L12 -> 15 | T12: A | U12: Base | V12: 25.92 | W12: 70.08 | X12: =SUM(M12:S12) -> 95 | Y12: 0.27:0.73 | Z12: 96 | AA12: 96 | AG12: Tank Prep | AH12: Load B (8-10) | AI12: Sail to Melaka
A13: 10 | B13: =1180-E13 -> 435 | E13: =SUM(F13:L13) -> 745 | F13: =F12-M12 -> 403.25 | G13: =G12-N12 -> 150 | H13: =H12-O12 -> 102 | I13: =I12-P12 -> 21.75 | J13: =J12-Q12 -> 68 | K13: =K12-R12 -> 0 | L13: =L12-S12 -> 0 | M13: 0 | N13: 0 | O13: =96*0.6 -> 57.6 | P13: 0 | Q13: =96*0.4 -> 38.4 | R13: 0 | S13: 0 | T13: A | U13: Base | V13: 20.4 | W13: 55.155556 | X13: =SUM(M13:S13) -> 96 | Y13: 0.27:0.73 | Z13: 75.555556 | AA13: 96 | AG13: Base: 400, A :150 | AH13: Wait | AI13: Sail to Melaka
A14: 11 | B14: =1180-E14 -> 531 | E14: =SUM(F14:L14) -> 649 | F14: =F13-M13 -> 403.25 | G14: =G13-N13 -> 150 | H14: =H13-O13 -> 44.4 | I14: =I13-P13 -> 21.75 | J14: =J13-Q13 -> 29.6 | K14: =K13-R13 -> 0 | L14: =L13-S13 -> 0 | M14: =(96-O14-Q14)*0.73 -> 16.06 | N14: =(96-O14-Q14)*0.27 -> 5.94 | O14: =H14 -> 44.4 | P14: 0 | Q14: =(O14/60)*40 -> 29.6 | R14: 0 | S14: 0 | T14: B | U14: Base | V14: 25.65 | W14: 69.35 | X14: =SUM(M14:S14) -> 96 | Y14: 0.27:0.73 | Z14: 95 | AA14: 95 | AH14: Sail | AI14: Discharge | AJ14: Load E (10-11)
A15: 12 | B15: =1180-E15 -> 307 | D15: 250E + 320F | E15: =SUM(F15:L15) -> 873 | F15: =F14-M14 -> 387.19 | G15: =G14-N14 -> 144.06 | H15: =H14-O14 -> 0 | I15: =I14-P14 -> 21.75 | J15: =J14-Q14 -> 0 | K15: =K14-R14 -> 0 | L15: =L14-S14+320 -> 320 | M15: =96*0.73 -> 70.08 | N15: =95*0.27 -> 25.65 | O15: 0 | P15: 0 | Q15: 0 | R15: 0 | S15: 0 | T15: B | U15: Base | V15: 25.65 | W15: 69.35 | X15: =SUM(M15:S15) -> 95.73 | Y15: 0.27:0.73 | Z15: 95 | AA15: 95 | AH15: Sail | AI15: Discharge | AJ15: Sail
A16: 13 | B16: =1180-E16 -> 402.73 | E16: =SUM(F16:L16) -> 777.27 | F16: =F15-M15 -> 317.11 | G16: =G15-N15 -> 118.41 | H16: =H15-O15 -> 0 | I16: =I15-P15 -> 21.75 | J16: =J15-Q15 -> 0 | K16: =K15-R15 -> 0 | L16: =L15-S15 -> 320 | M16: =96*0.73 -> 70.08 | N16: =95*0.27 -> 25.65 | O16: 0 | P16: 0 | Q16: 0 | R16: 0 | S16: 0 | T16: B | U16: Base | V16: 25.65 | W16: 69.35 | X16: =SUM(M16:S16) -> 95.73 | Y16: 0.27:0.73 | Z16: 95 | AA16: 95 | AH16: Discharge | AI16: Tank Prep | AJ16: Sail
A17: 14 | B17: =1180-E17 -> 348.46 | D17: 150B | E17: =SUM(F17:L17) -> 831.54 | F17: =F16-M16 -> 247.03 | G17: =G16-N16 -> 92.76 | H17: =H16-O16+150 -> 150 | I17: =I16-P16 -> 21.75 | J17: =J16-Q16 -> 0 | K17: =K16-R16 -> 0 | L17: =L16-S16 -> 320 | M17: =96*0.73 -> 70.08 | N17: =95*0.27 -> 25.65 | O17: 0 | P17: 0 | Q17: 0 | R17: 0 | S17: 0 | T17: B | U17: Base | V17: 24.79726 | W17: 67.044444 | X17: =SUM(M17:S17) -> 95.73 | Y17: 0.27:0.73 | Z17: 91.841705 | AA17: 95 | AH17: Discharge | AI17: Tank Prep | AJ17: Sail
A18: 15 | B18: =1180-E18 -> 444.19 | E18: =SUM(F18:L18) -> 735.81 | F18: =F17-M17 -> 176.95 | G18: =G17-N17 -> 67.11 | H18: =H17-O17 -> 150 | I18: =I17-P17 -> 21.75 | J18: =J17-Q17 -> 0 | K18: =K17-R17 -> 0 | L18: =L17-S17 -> 320 | M18: =96*0.73 -> 70.08 | N18: =95*0.27 -> 25.65 | O18: 0 | P18: 0 | Q18: 0 | R18: 0 | S18: 0 | T18: C | V18: 7.1054274e-15 | W18: 0 | X18: =SUM(M18:S18) -> 95.73 | Y18: 1.00:0.00 | Z18: 7.1054274e-15 | AA18: 96 | AH18: Tank Prep | AI18: Tank Prep | AJ18: Discharge
A19: 16 | B19: =1180-E19 -> -10.08 | C19: 1 | D19: 550E | E19: =SUM(F19:L19) -> 1190.08 | F19: =F18-M18 -> 106.87 | G19: =G18-N18 -> 41.46 | H19: =H18-O18 -> 150 | I19: =I18-P18 -> 21.75 | J19: =J18-Q18 -> 0 | K19: =K18-R18+550 -> 550 | L19: =L18-S18 -> 320 | M19: 70 | N19: 26 | O19: 0 | P19: 0 | Q19: 0 | R19: 0 | S19: 0 | T19: B | V19: 95 | W19: 0 | X19: =SUM(M19:S19) -> 96 | Y19: 1.00:0.00 | Z19: 95 | AA19: 95 | AH19: Tank Prep | AI19: F: 320 | AJ19: Discharge
